Workbook

Sheet COB_CA
A1: Canadian Cost of Borrowing (COB) Disclosure -- inputs & summary
A2: Borrower-facing COST-OF-BORROWING ESTIMATE, not a certified regulatory disclosure -- see docs/new-req/006-cost-of-borrowing-disclosure.md. Blue cells = edit; black = computed. Every input field stays visible for every Flow (no macros can hide/show fields) -- pick Flow/Product type/Rate type below, then read the four computed helper rows to see which date field, trigger-rate, compounding, and accrued-interest rules actually apply; unused fields for your Flow are simply ignored by the formulas.
A4: Flow / product / rate-type selection | D4: Frequency | E4: Payments/Yr
A5: Flow | B5: New mortgage | D5: monthly | E5: 12
A6: Product type | B6: mortgage | D6: semiMonthly | E6: 24
A7: Rate type | B7: variable | D7: biweekly | E7: 26
D8: weekly | E8: 52
A9: Date field used (per spec's Flow table) | B9: =IF(OR(B5="New mortgage",B5="New loan"),"Pre-approval date","Renewal date")
A10: Accrued-interest carry-forward applies? | B10: =IF(OR(B5="Existing mortgage",B5="Existing loan",B5="Payment change",B5="Variable rate payment change"),"Yes","No")
A11: Compounding convention (eq. 1 / eq. 2) | B11: =IF(AND(B6="mortgage",B7="fixed"),"Semi-annual (Interest Act s.6, CONFIRMED)","Monthly (best-available default, eq. 2)")
A12: Trigger rate computed? (mortgage + variable only) | B12: =IF(AND(B6="mortgage",B7="variable"),"Yes","No / N/A")
A14: Inputs -- common to every flow
A15: Loan amount ($) / current outstanding balance ($) | B15: 400000 | C15: New flows: the new loan/mortgage face amount. Existing/Payment-change flows: enter the CURRENT OUTSTANDING BALANCE here instead (same field, reused per spec).
A16: Contract rate, nominal annual (%) | B16: 5
A17: Payment frequency | B17: monthly
A18: Term years (CONTRACT TERM, not amortization) | B18: 5
A19: Term months (contract term, extra months) | B19: 0
A20: Remaining amortization years | B20: 25
A21: Remaining amortization months (extra) | B21: 0
A22: First payment date | B22: 2026-02-01
A23: End date (this term's maturity/renewal date) | B23: 2031-01-01
A25: Inputs -- flow-conditional
A26: Disbursal date (new flows only) | B26: 2026-01-15
A27: Pre-approval date (new mortgage / new loan only) | B27: 2025-12-01
A28: Renewal date (existing/payment-change flows only) | B28: 2026-01-01
A29: Accrued interest ($) -- existing/renewal flows only | B29: 0 | C29: Judgment call: capitalized into this term's opening balance when the carry-forward row above reads Yes -- see docs/new-req/006's Excel implementation notes.
A30: Semi-annual compounding reference date (fixed mortgages only) | B30: 2026-01-01 | C30: Display/reference only -- eq. 1's periodic-rate conversion does not depend on this date (see spec 006, equation 1). Not used in any formula below.
A32: Fees (equation 7's fee-inclusion list)
A33: Financed? and Included in COB? are INDEPENDENT flags (spec 006 eq. 7) -- e.g. a prepayment penalty or discharge fee is never included in cob_amount even if financed.
A35: Fee name | B35: Amount ($) | C35: Financed? (Y/N) | D35: Included in COB? (Y/N)
A36: Administrative charge | B36: 200 | C36: N | D36: Y
A37: Appraisal fee (lender-required) | B37: 400 | C37: N | D37: Y
A38: Broker fee (paid by lender to broker, included in amount borrowed) | B38: 500 | C38: Y | D38: Y
A39: Prepayment penalty | B39: 0 | C39: N | D39: N
A40: Discharge fee | B40: 0 | C40: N | D40: N
A41: Mortgage default insurance premium (high-ratio) | B41: 0 | C41: Y | D41: N
A43: Derived quantities
A44: Payments per year (n) | B44: =INDEX($E$5:$E$8,MATCH(B17,$D$5:$D$8,0))
A45: Periodic rate i_period (eq. 1 / eq. 2) | B45: =IF(AND(B6="mortgage",B7="fixed"),(1+B16/100/2)^(2/B44)-1,B16/100/B44)
A46: Total fees | B46: =SUM($B$36:$B$41)
...

Sheet COB_CA_Schedule
A1: COB_CA amortization schedule (computed) -- do not edit
A2: One row per period within the CURRENT CONTRACT TERM ONLY (not the full amortization) -- bounded to 520 rows. Rows past the term's own length (COB_CA!B58) freeze at the term's own ending balance; rows past an early full payoff (rare -- only if remaining amortization is shorter than the term) read $0, same self-stabilizing technique used throughout COB_Calculator.xlsx (see docs/new-req/005).
A4: Period # | B4: Period Date | C4: Beginning Balance | D4: Interest | E4: Principal | F4: Payment | G4: Ending Balance | H4: Counted in term totals?
A5: 1 | B5: =IF(COB_CA!$B$44=12,DATE(YEAR(COB_CA!$B$22)+INT((MONTH(COB_CA!$B$22)-1+0)/12),MOD(MONTH(COB_CA!$B$22)-1+0,12)+1,1)+(DAY(COB_CA!$B$22)-1),IF(COB_CA!$B$44=24,COB_CA!$B$22+ROUND((0*365.25)/24,0),IF(COB_CA!$B$44=26,COB_CA!$B$22+0,COB_CA!$B$22+0))) | C5: =COB_CA!$B$52 | D5: =IF((A5<=COB_CA!$B$58),ROUND(C5*COB_CA!$B$45,2),0) | E5: =IF((A5<=COB_CA!$B$58),IF(AND((A5<=COB_CA!$B$58),ROUND(C5-ROUND(COB_CA!$B$59-D5,2),2)<=0),C5,ROUND(COB_CA!$B$59-D5,2)),0) | F5: =IF((A5<=COB_CA!$B$58),IF(AND((A5<=COB_CA!$B$58),ROUND(C5-ROUND(COB_CA!$B$59-D5,2),2)<=0),ROUND(D5+E5,2),COB_CA!$B$59),0) | G5: =IF((A5<=COB_CA!$B$58),IF(AND((A5<=COB_CA!$B$58),ROUND(C5-ROUND(COB_CA!$B$59-D5,2),2)<=0),0,ROUND(C5-E5,2)),C5) | H5: =(A5<=COB_CA!$B$58)
A6: 2 | B6: =IF(COB_CA!$B$44=12,DATE(YEAR(COB_CA!$B$22)+INT((MONTH(COB_CA!$B$22)-1+1)/12),MOD(MONTH(COB_CA!$B$22)-1+1,12)+1,1)+(DAY(COB_CA!$B$22)-1),IF(COB_CA!$B$44=24,COB_CA!$B$22+ROUND((1*365.25)/24,0),IF(COB_CA!$B$44=26,COB_CA!$B$22+14,COB_CA!$B$22+7))) | C6: =G5 | D6: =IF((A6<=COB_CA!$B$58),ROUND(C6*COB_CA!$B$45,2),0) | E6: =IF((A6<=COB_CA!$B$58),IF(AND((A6<=COB_CA!$B$58),ROUND(C6-ROUND(COB_CA!$B$59-D6,2),2)<=0),C6,ROUND(COB_CA!$B$59-D6,2)),0) | F6: =IF((A6<=COB_CA!$B$58),IF(AND((A6<=COB_CA!$B$58),ROUND(C6-ROUND(COB_CA!$B$59-D6,2),2)<=0),ROUND(D6+E6,2),COB_CA!$B$59),0) | G6: =IF((A6<=COB_CA!$B$58),IF(AND((A6<=COB_CA!$B$58),ROUND(C6-ROUND(COB_CA!$B$59-D6,2),2)<=0),0,ROUND(C6-E6,2)),C6) | H6: =AND(H5,C5>0,(A6<=COB_CA!$B$58))
A7: 3 | B7: =IF(COB_CA!$B$44=12,DATE(YEAR(COB_CA!$B$22)+INT((MONTH(COB_CA!$B$22)-1+2)/12),MOD(MONTH(COB_CA!$B$22)-1+2,12)+1,1)+(DAY(COB_CA!$B$22)-1),IF(COB_CA!$B$44=24,COB_CA!$B$22+ROUND((2*365.25)/24,0),IF(COB_CA!$B$44=26,COB_CA!$B$22+28,COB_CA!$B$22+14))) | C7: =G6 | D7: =IF((A7<=COB_CA!$B$58),ROUND(C7*COB_CA!$B$45,2),0) | E7: =IF((A7<=COB_CA!$B$58),IF(AND((A7<=COB_CA!$B$58),ROUND(C7-ROUND(COB_CA!$B$59-D7,2),2)<=0),C7,ROUND(COB_CA!$B$59-D7,2)),0) | F7: =IF((A7<=COB_CA!$B$58),IF(AND((A7<=COB_CA!$B$58),ROUND(C7-ROUND(COB_CA!$B$59-D7,2),2)<=0),ROUND(D7+E7,2),COB_CA!$B$59),0) | G7: =IF((A7<=COB_CA!$B$58),IF(AND((A7<=COB_CA!$B$58),ROUND(C7-ROUND(COB_CA!$B$59-D7,2),2)<=0),0,ROUND(C7-E7,2)),C7) | H7: =AND(H6,C6>0,(A7<=COB_CA!$B$58))
A8: 4 | B8: =IF(COB_CA!$B$44=12,DATE(YEAR(COB_CA!$B$22)+INT((MONTH(COB_CA!$B$22)-1+3)/12),MOD(MONTH(COB_CA!$B$22)-1+3,12)+1,1)+(DAY(COB_CA!$B$22)-1),IF(COB_CA!$B$44=24,COB_CA!$B$22+ROUND((3*365.25)/24,0),IF(COB_CA!$B$44=26,COB_CA!$B$22+42,COB_CA!$B$22+21))) | C8: =G7 | D8: =IF((A8<=COB_CA!$B$58),ROUND(C8*COB_CA!$B$45,2),0) | E8: =IF((A8<=COB_CA!$B$58),IF(AND((A8<=COB_CA!$B$58),ROUND(C8-ROUND(COB_CA!$B$59-D8,2),2)<=0),C8,ROUND(COB_CA!$B$59-D8,2)),0) | F8: =IF((A8<=COB_CA!$B$58),IF(AND((A8<=COB_CA!$B$58),ROUND(C8-ROUND(COB_CA!$B$59-D8,2),2)<=0),ROUND(D8+E8,2),COB_CA!$B$59),0) | G8: =IF((A8<=COB_CA!$B$58),IF(AND((A8<=COB_CA!$B$58),ROUND(C8-ROUND(COB_CA!$B$59-D8,2),2)<=0),0,ROUND(C8-E8,2)),C8) | H8: =AND(H7,C7>0,(A8<=COB_CA!$B$58))
A9: 5 | B9: =IF(COB_CA!$B$44=12,DATE(YEAR(COB_CA!$B$22)+INT((MONTH(COB_CA!$B$22)-1+4)/12),MOD(MONTH(COB_CA!$B$22)-1+4,12)+1,1)+(DAY(COB_CA!$B$22)-1),IF(COB_CA!$B$44=24,COB_CA!$B$22+ROUND((4*365.25)/24,0),IF(COB_CA!$B$44=26,COB_CA!$B$22+56,COB_CA!$B$22+28))) | C9: =G8 | D9: =IF((A9<=COB_CA!$B$58),ROUND(C9*COB_CA!$B$45,2),0) | E9: =IF((A9<=COB_CA!$B$58),IF(AND((A9<=COB_CA!$B$58),ROUND(C9-ROUND(COB_CA!$B$59-D9,2),2)<=0),C9,ROUND(COB_CA!$B$59-D9,2)),0) | F9: =IF((A9<=COB_CA!$B$58),IF(AND((A9<=COB_CA!$B$58),ROUND(C9-ROUND(COB_CA!$B$59-D9,2),2)<=0),ROUND(D9+E9,2),COB_CA!$B$59),0) | G9: =IF((A9<=COB_CA!$B$58),IF(AND((A9<=COB_CA!$B$58),ROUND(C9-ROUND(COB_CA!$B$59-D9,2),2)<=0),0,ROUND(C9-E9,2)),C9) | H9: =AND(H8,C8>0,(A9<=COB_CA!$B$58))
A10: 6 | B10: =IF(COB_CA!$B$44=12,DATE(YEAR(COB_CA!$B$22)+INT((MONTH(COB_CA!$B$22)-1+5)/12),MOD(MONTH(COB_CA!$B$22)-1+5,12)+1,1)+(DAY(COB_CA!$B$22)-1),IF(COB_CA!$B$44=24,COB_CA!$B$22+ROUND((5*365.25)/24,0),IF(COB_CA!$B$44=26,COB_CA!$B$22+70,COB_CA!$B$22+35))) | C10: =G9 | D10: =IF((A10<=COB_CA!$B$58),ROUND(C10*COB_CA!$B$45,2),0) | E10: =IF((A10<=COB_CA!$B$58),IF(AND((A10<=COB_CA!$B$58),ROUND(C10-ROUND(COB_CA!$B$59-D10,2),2)<=0),C10,ROUND(COB_CA!$B$59-D10,2)),0) | F10: =IF((A10<=COB_CA!$B$58),IF(AND((A10<=COB_CA!$B$58),ROUND(C10-ROUND(COB_CA!$B$59-D10,2),2)<=0),ROUND(D10+E10,2),COB_CA!$B$59),0) | G10: =IF((A10<=COB_CA!$B$58),IF(AND((A10<=COB_CA!$B$58),ROUND(C10-ROUND(COB_CA!$B$59-D10,2),2)<=0),0,ROUND(C10-E10,2)),C10) | H10: =AND(H9,C9>0,(A10<=COB_CA!$B$58))
A11: 7 | B11: =IF(COB_CA!$B$44=12,DATE(YEAR(COB_CA!$B$22)+INT((MONTH(COB_CA!$B$22)-1+6)/12),MOD(MONTH(COB_CA!$B$22)-1+6,12)+1,1)+(DAY(COB_CA!$B$22)-1),IF(COB_CA!$B$44=24,COB_CA!$B$22+ROUND((6*365.25)/24,0),IF(COB_CA!$B$44=26,COB_CA!$B$22+84,COB_CA!$B$22+42))) | C11: =G10 | D11: =IF((A11<=COB_CA!$B$58),ROUND(C11*COB_CA!$B$45,2),0) | E11: =IF((A11<=COB_CA!$B$58),IF(AND((A11<=COB_CA!$B$58),ROUND(C11-ROUND(COB_CA!$B$59-D11,2),2)<=0),C11,ROUND(COB_CA!$B$59-D11,2)),0) | F11: =IF((A11<=COB_CA!$B$58),IF(AND((A11<=COB_CA!$B$58),ROUND(C11-ROUND(COB_CA!$B$59-D11,2),2)<=0),ROUND(D11+E11,2),COB_CA!$B$59),0) | G11: =IF((A11<=COB_CA!$B$58),IF(AND((A11<=COB_CA!$B$58),ROUND(C11-ROUND(COB_CA!$B$59-D11,2),2)<=0),0,ROUND(C11-E11,2)),C11) | H11: =AND(H10,C10>0,(A11<=COB_CA!$B$58))
A12: 8 | B12: =IF(COB_CA!$B$44=12,DATE(YEAR(COB_CA!$B$22)+INT((MONTH(COB_CA!$B$22)-1+7)/12),MOD(MONTH(COB_CA!$B$22)-1+7,12)+1,1)+(DAY(COB_CA!$B$22)-1),IF(COB_CA!$B$44=24,COB_CA!$B$22+ROUND((7*365.25)/24,0),IF(COB_CA!$B$44=26,COB_CA!$B$22+98,COB_CA!$B$22+49))) | C12: =G11 | D12: =IF((A12<=COB_CA!$B$58),ROUND(C12*COB_CA!$B$45,2),0) | E12: =IF((A12<=COB_CA!$B$58),IF(AND((A12<=COB_CA!$B$58),ROUND(C12-ROUND(COB_CA!$B$59-D12,2),2)<=0),C12,ROUND(COB_CA!$B$59-D12,2)),0) | F12: =IF((A12<=COB_CA!$B$58),IF(AND((A12<=COB_CA!$B$58),ROUND(C12-ROUND(COB_CA!$B$59-D12,2),2)<=0),ROUND(D12+E12,2),COB_CA!$B$59),0) | G12: =IF((A12<=COB_CA!$B$58),IF(AND((A12<=COB_CA!$B$58),ROUND(C12-ROUND(COB_CA!$B$59-D12,2),2)<=0),0,ROUND(C12-E12,2)),C12) | H12: =AND(H11,C11>0,(A12<=COB_CA!$B$58))
A13: 9 | B13: =IF(COB_CA!$B$44=12,DATE(YEAR(COB_CA!$B$22)+INT((MONTH(COB_CA!$B$22)-1+8)/12),MOD(MONTH(COB_CA!$B$22)-1+8,12)+1,1)+(DAY(COB_CA!$B$22)-1),IF(COB_CA!$B$44=24,COB_CA!$B$22+ROUND((8*365.25)/24,0),IF(COB_CA!$B$44=26,COB_CA!$B$22+112,COB_CA!$B$22+56))) | C13: =G12 | D13: =IF((A13<=COB_CA!$B$58),ROUND(C13*COB_CA!$B$45,2),0) | E13: =IF((A13<=COB_CA!$B$58),IF(AND((A13<=COB_CA!$B$58),ROUND(C13-ROUND(COB_CA!$B$59-D13,2),2)<=0),C13,ROUND(COB_CA!$B$59-D13,2)),0) | F13: =IF((A13<=COB_CA!$B$58),IF(AND((A13<=COB_CA!$B$58),ROUND(C13-ROUND(COB_CA!$B$59-D13,2),2)<=0),ROUND(D13+E13,2),COB_CA!$B$59),0) | G13: =IF((A13<=COB_CA!$B$58),IF(AND((A13<=COB_CA!$B$58),ROUND(C13-ROUND(COB_CA!$B$59-D13,2),2)<=0),0,ROUND(C13-E13,2)),C13) | H13: =AND(H12,C12>0,(A13<=COB_CA!$B$58))
A14: 10 | B14: =IF(COB_CA!$B$44=12,DATE(YEAR(COB_CA!$B$22)+INT((MONTH(COB_CA!$B$22)-1+9)/12),MOD(MONTH(COB_CA!$B$22)-1+9,12)+1,1)+(DAY(COB_CA!$B$22)-1),IF(COB_CA!$B$44=24,COB_CA!$B$22+ROUND((9*365.25)/24,0),IF(COB_CA!$B$44=26,COB_CA!$B$22+126,COB_CA!$B$22+63))) | C14: =G13 | D14: =IF((A14<=COB_CA!$B$58),ROUND(C14*COB_CA!$B$45,2),0) | E14: =IF((A14<=COB_CA!$B$58),IF(AND((A14<=COB_CA!$B$58),ROUND(C14-ROUND(COB_CA!$B$59-D14,2),2)<=0),C14,ROUND(COB_CA!$B$59-D14,2)),0) | F14: =IF((A14<=COB_CA!$B$58),IF(AND((A14<=COB_CA!$B$58),ROUND(C14-ROUND(COB_CA!$B$59-D14,2),2)<=0),ROUND(D14+E14,2),COB_CA!$B$59),0) | G14: =IF((A14<=COB_CA!$B$58),IF(AND((A14<=COB_CA!$B$58),ROUND(C14-ROUND(COB_CA!$B$59-D14,2),2)<=0),0,ROUND(C14-E14,2)),C14) | H14: =AND(H13,C13>0,(A14<=COB_CA!$B$58))
A15: 11 | B15: =IF(COB_CA!$B$44=12,DATE(YEAR(COB_CA!$B$22)+INT((MONTH(COB_CA!$B$22)-1+10)/12),MOD(MONTH(COB_CA!$B$22)-1+10,12)+1,1)+(DAY(COB_CA!$B$22)-1),IF(COB_CA!$B$44=24,COB_CA!$B$22+ROUND((10*365.25)/24,0),IF(COB_CA!$B$44=26,COB_CA!$B$22+140,COB_CA!$B$22+70))) | C15: =G14 | D15: =IF((A15<=COB_CA!$B$58),ROUND(C15*COB_CA!$B$45,2),0) | E15: =IF((A15<=COB_CA!$B$58),IF(AND((A15<=COB_CA!$B$58),ROUND(C15-ROUND(COB_CA!$B$59-D15,2),2)<=0),C15,ROUND(COB_CA!$B$59-D15,2)),0) | F15: =IF((A15<=COB_CA!$B$58),IF(AND((A15<=COB_CA!$B$58),ROUND(C15-ROUND(COB_CA!$B$59-D15,2),2)<=0),ROUND(D15+E15,2),COB_CA!$B$59),0) | G15: =IF((A15<=COB_CA!$B$58),IF(AND((A15<=COB_CA!$B$58),ROUND(C15-ROUND(COB_CA!$B$59-D15,2),2)<=0),0,ROUND(C15-E15,2)),C15) | H15: =AND(H14,C14>0,(A15<=COB_CA!$B$58))
A16: 12 | B16: =IF(COB_CA!$B$44=12,DATE(YEAR(COB_CA!$B$22)+INT((MONTH(COB_CA!$B$22)-1+11)/12),MOD(MONTH(COB_CA!$B$22)-1+11,12)+1,1)+(DAY(COB_CA!$B$22)-1),IF(COB_CA!$B$44=24,COB_CA!$B$22+ROUND((11*365.25)/24,0),IF(COB_CA!$B$44=26,COB_CA!$B$22+154,COB_CA!$B$22+77))) | C16: =G15 | D16: =IF((A16<=COB_CA!$B$58),ROUND(C16*COB_CA!$B$45,2),0) | E16: =IF((A16<=COB_CA!$B$58),IF(AND((A16<=COB_CA!$B$58),ROUND(C16-ROUND(COB_CA!$B$59-D16,2),2)<=0),C16,ROUND(COB_CA!$B$59-D16,2)),0) | F16: =IF((A16<=COB_CA!$B$58),IF(AND((A16<=COB_CA!$B$58),ROUND(C16-ROUND(COB_CA!$B$59-D16,2),2)<=0),ROUND(D16+E16,2),COB_CA!$B$59),0) | G16: =IF((A16<=COB_CA!$B$58),IF(AND((A16<=COB_CA!$B$58),ROUND(C16-ROUND(COB_CA!$B$59-D16,2),2)<=0),0,ROUND(C16-E16,2)),C16) | H16: =AND(H15,C15>0,(A16<=COB_CA!$B$58))
A17: 13 | B17: =IF(COB_CA!$B$44=12,DATE(YEAR(COB_CA!$B$22)+INT((MONTH(COB_CA!$B$22)-1+12)/12),MOD(MONTH(COB_CA!$B$22)-1+12,12)+1,1)+(DAY(COB_CA!$B$22)-1),IF(COB_CA!$B$44=24,COB_CA!$B$22+ROUND((12*365.25)/24,0),IF(COB_CA!$B$44=26,COB_CA!$B$22+168,COB_CA!$B$22+84))) | C17: =G16 | D17: =IF((A17<=COB_CA!$B$58),ROUND(C17*COB_CA!$B$45,2),0) | E17: =IF((A17<=COB_CA!$B$58),IF(AND((A17<=COB_CA!$B$58),ROUND(C17-ROUND(COB_CA!$B$59-D17,2),2)<=0),C17,ROUND(COB_CA!$B$59-D17,2)),0) | F17: =IF((A17<=COB_CA!$B$58),IF(AND((A17<=COB_CA!$B$58),ROUND(C17-ROUND(COB_CA!$B$59-D17,2),2)<=0),ROUND(D17+E17,2),COB_CA!$B$59),0) | G17: =IF((A17<=COB_CA!$B$58),IF(AND((A17<=COB_CA!$B$58),ROUND(C17-ROUND(COB_CA!$B$59-D17,2),2)<=0),0,ROUND(C17-E17,2)),C17) | H17: =AND(H16,C16>0,(A17<=COB_CA!$B$58))
A18: 14 | B18: =IF(COB_CA!$B$44=12,DATE(YEAR(COB_CA!$B$22)+INT((MONTH(COB_CA!$B$22)-1+13)/12),MOD(MONTH(COB_CA!$B$22)-1+13,12)+1,1)+(DAY(COB_CA!$B$22)-1),IF(COB_CA!$B$44=24,COB_CA!$B$22+ROUND((13*365.25)/24,0),IF(COB_CA!$B$44=26,COB_CA!$B$22+182,COB_CA!$B$22+91))) | C18: =G17 | D18: =IF((A18<=COB_CA!$B$58),ROUND(C18*COB_CA!$B$45,2),0) | E18: =IF((A18<=COB_CA!$B$58),IF(AND((A18<=COB_CA!$B$58),ROUND(C18-ROUND(COB_CA!$B$59-D18,2),2)<=0),C18,ROUND(COB_CA!$B$59-D18,2)),0) | F18: =IF((A18<=COB_CA!$B$58),IF(AND((A18<=COB_CA!$B$58),ROUND(C18-ROUND(COB_CA!$B$59-D18,2),2)<=0),ROUND(D18+E18,2),COB_CA!$B$59),0) | G18: =IF((A18<=COB_CA!$B$58),IF(AND((A18<=COB_CA!$B$58),ROUND(C18-ROUND(COB_CA!$B$59-D18,2),2)<=0),0,ROUND(C18-E18,2)),C18) | H18: =AND(H17,C17>0,(A18<=COB_CA!$B$58))
A19: 15 | B19: =IF(COB_CA!$B$44=12,DATE(YEAR(COB_CA!$B$22)+INT((MONTH(COB_CA!$B$22)-1+14)/12),MOD(MONTH(COB_CA!$B$22)-1+14,12)+1,1)+(DAY(COB_CA!$B$22)-1),IF(COB_CA!$B$44=24,COB_CA!$B$22+ROUND((14*365.25)/24,0),IF(COB_CA!$B$44=26,COB_CA!$B$22+196,COB_CA!$B$22+98))) | C19: =G18 | D19: =IF((A19<=COB_CA!$B$58),ROUND(C19*COB_CA!$B$45,2),0) | E19: =IF((A19<=COB_CA!$B$58),IF(AND((A19<=COB_CA!$B$58),ROUND(C19-ROUND(COB_CA!$B$59-D19,2),2)<=0),C19,ROUND(COB_CA!$B$59-D19,2)),0) | F19: =IF((A19<=COB_CA!$B$58),IF(AND((A19<=COB_CA!$B$58),ROUND(C19-ROUND(COB_CA!$B$59-D19,2),2)<=0),ROUND(D19+E19,2),COB_CA!$B$59),0) | G19: =IF((A19<=COB_CA!$B$58),IF(AND((A19<=COB_CA!$B$58),ROUND(C19-ROUND(COB_CA!$B$59-D19,2),2)<=0),0,ROUND(C19-E19,2)),C19) | H19: =AND(H18,C18>0,(A19<=COB_CA!$B$58))
A20: 16 | B20: =IF(COB_CA!$B$44=12,DATE(YEAR(COB_CA!$B$22)+INT((MONTH(COB_CA!$B$22)-1+15)/12),MOD(MONTH(COB_CA!$B$22)-1+15,12)+1,1)+(DAY(COB_CA!$B$22)-1),IF(COB_CA!$B$44=24,COB_CA!$B$22+ROUND((15*365.25)/24,0),IF(COB_CA!$B$44=26,COB_CA!$B$22+210,COB_CA!$B$22+105))) | C20: =G19 | D20: =IF((A20<=COB_CA!$B$58),ROUND(C20*COB_CA!$B$45,2),0) | E20: =IF((A20<=COB_CA!$B$58),IF(AND((A20<=COB_CA!$B$58),ROUND(C20-ROUND(COB_CA!$B$59-D20,2),2)<=0),C20,ROUND(COB_CA!$B$59-D20,2)),0) | F20: =IF((A20<=COB_CA!$B$58),IF(AND((A20<=COB_CA!$B$58),ROUND(C20-ROUND(COB_CA!$B$59-D20,2),2)<=0),ROUND(D20+E20,2),COB_CA!$B$59),0) | G20: =IF((A20<=COB_CA!$B$58),IF(AND((A20<=COB_CA!$B$58),ROUND(C20-ROUND(COB_CA!$B$59-D20,2),2)<=0),0,ROUND(C20-E20,2)),C20) | H20: =AND(H19,C19>0,(A20<=COB_CA!$B$58))
A21: 17 | B21: =IF(COB_CA!$B$44=12,DATE(YEAR(COB_CA!$B$22)+INT((MONTH(COB_CA!$B$22)-1+16)/12),MOD(MONTH(COB_CA!$B$22)-1+16,12)+1,1)+(DAY(COB_CA!$B$22)-1),IF(COB_CA!$B$44=24,COB_CA!$B$22+ROUND((16*365.25)/24,0),IF(COB_CA!$B$44=26,COB_CA!$B$22+224,COB_CA!$B$22+112))) | C21: =G20 | D21: =IF((A21<=COB_CA!$B$58),ROUND(C21*COB_CA!$B$45,2),0) | E21: =IF((A21<=COB_CA!$B$58),IF(AND((A21<=COB_CA!$B$58),ROUND(C21-ROUND(COB_CA!$B$59-D21,2),2)<=0),C21,ROUND(COB_CA!$B$59-D21,2)),0) | F21: =IF((A21<=COB_CA!$B$58),IF(AND((A21<=COB_CA!$B$58),ROUND(C21-ROUND(COB_CA!$B$59-D21,2),2)<=0),ROUND(D21+E21,2),COB_CA!$B$59),0) | G21: =IF((A21<=COB_CA!$B$58),IF(AND((A21<=COB_CA!$B$58),ROUND(C21-ROUND(COB_CA!$B$59-D21,2),2)<=0),0,ROUND(C21-E21,2)),C21) | H21: =AND(H20,C20>0,(A21<=COB_CA!$B$58))
A22: 18 | B22: =IF(COB_CA!$B$44=12,DATE(YEAR(COB_CA!$B$22)+INT((MONTH(COB_CA!$B$22)-1+17)/12),MOD(MONTH(COB_CA!$B$22)-1+17,12)+1,1)+(DAY(COB_CA!$B$22)-1),IF(COB_CA!$B$44=24,COB_CA!$B$22+ROUND((17*365.25)/24,0),IF(COB_CA!$B$44=26,COB_CA!$B$22+238,COB_CA!$B$22+119))) | C22: =G21 | D22: =IF((A22<=COB_CA!$B$58),ROUND(C22*COB_CA!$B$45,2),0) | E22: =IF((A22<=COB_CA!$B$58),IF(AND((A22<=COB_CA!$B$58),ROUND(C22-ROUND(COB_CA!$B$59-D22,2),2)<=0),C22,ROUND(COB_CA!$B$59-D22,2)),0) | F22: =IF((A22<=COB_CA!$B$58),IF(AND((A22<=COB_CA!$B$58),ROUND(C22-ROUND(COB_CA!$B$59-D22,2),2)<=0),ROUND(D22+E22,2),COB_CA!$B$59),0) | G22: =IF((A22<=COB_CA!$B$58),IF(AND((A22<=COB_CA!$B$58),ROUND(C22-ROUND(COB_CA!$B$59-D22,2),2)<=0),0,ROUND(C22-E22,2)),C22) | H22: =AND(H21,C21>0,(A22<=COB_CA!$B$58))
A23: 19 | B23: =IF(COB_CA!$B$44=12,DATE(YEAR(COB_CA!$B$22)+INT((MONTH(COB_CA!$B$22)-1+18)/12),MOD(MONTH(COB_CA!$B$22)-1+18,12)+1,1)+(DAY(COB_CA!$B$22)-1),IF(COB_CA!$B$44=24,COB_CA!$B$22+ROUND((18*365.25)/24,0),IF(COB_CA!$B$44=26,COB_CA!$B$22+252,COB_CA!$B$22+126))) | C23: =G22 | D23: =IF((A23<=COB_CA!$B$58),ROUND(C23*COB_CA!$B$45,2),0) | E23: =IF((A23<=COB_CA!$B$58),IF(AND((A23<=COB_CA!$B$58),ROUND(C23-ROUND(COB_CA!$B$59-D23,2),2)<=0),C23,ROUND(COB_CA!$B$59-D23,2)),0) | F23: =IF((A23<=COB_CA!$B$58),IF(AND((A23<=COB_CA!$B$58),ROUND(C23-ROUND(COB_CA!$B$59-D23,2),2)<=0),ROUND(D23+E23,2),COB_CA!$B$59),0) | G23: =IF((A23<=COB_CA!$B$58),IF(AND((A23<=COB_CA!$B$58),ROUND(C23-ROUND(COB_CA!$B$59-D23,2),2)<=0),0,ROUND(C23-E23,2)),C23) | H23: =AND(H22,C22>0,(A23<=COB_CA!$B$58))
A24: 20 | B24: =IF(COB_CA!$B$44=12,DATE(YEAR(COB_CA!$B$22)+INT((MONTH(COB_CA!$B$22)-1+19)/12),MOD(MONTH(COB_CA!$B$22)-1+19,12)+1,1)+(DAY(COB_CA!$B$22)-1),IF(COB_CA!$B$44=24,COB_CA!$B$22+ROUND((19*365.25)/24,0),IF(COB_CA!$B$44=26,COB_CA!$B$22+266,COB_CA!$B$22+133))) | C24: =G23 | D24: =IF((A24<=COB_CA!$B$58),ROUND(C24*COB_CA!$B$45,2),0) | E24: =IF((A24<=COB_CA!$B$58),IF(AND((A24<=COB_CA!$B$58),ROUND(C24-ROUND(COB_CA!$B$59-D24,2),2)<=0),C24,ROUND(COB_CA!$B$59-D24,2)),0) | F24: =IF((A24<=COB_CA!$B$58),IF(AND((A24<=COB_CA!$B$58),ROUND(C24-ROUND(COB_CA!$B$59-D24,2),2)<=0),ROUND(D24+E24,2),COB_CA!$B$59),0) | G24: =IF((A24<=COB_CA!$B$58),IF(AND((A24<=COB_CA!$B$58),ROUND(C24-ROUND(COB_CA!$B$59-D24,2),2)<=0),0,ROUND(C24-E24,2)),C24) | H24: =AND(H23,C23>0,(A24<=COB_CA!$B$58))
A25: 21 | B25: =IF(COB_CA!$B$44=12,DATE(YEAR(COB_CA!$B$22)+INT((MONTH(COB_CA!$B$22)-1+20)/12),MOD(MONTH(COB_CA!$B$22)-1+20,12)+1,1)+(DAY(COB_CA!$B$22)-1),IF(COB_CA!$B$44=24,COB_CA!$B$22+ROUND((20*365.25)/24,0),IF(COB_CA!$B$44=26,COB_CA!$B$22+280,COB_CA!$B$22+140))) | C25: =G24 | D25: =IF((A25<=COB_CA!$B$58),ROUND(C25*COB_CA!$B$45,2),0) | E25: =IF((A25<=COB_CA!$B$58),IF(AND((A25<=COB_CA!$B$58),ROUND(C25-ROUND(COB_CA!$B$59-D25,2),2)<=0),C25,ROUND(COB_CA!$B$59-D25,2)),0) | F25: =IF((A25<=COB_CA!$B$58),IF(AND((A25<=COB_CA!$B$58),ROUND(C25-ROUND(COB_CA!$B$59-D25,2),2)<=0),ROUND(D25+E25,2),COB_CA!$B$59),0) | G25: =IF((A25<=COB_CA!$B$58),IF(AND((A25<=COB_CA!$B$58),ROUND(C25-ROUND(COB_CA!$B$59-D25,2),2)<=0),0,ROUND(C25-E25,2)),C25) | H25: =AND(H24,C24>0,(A25<=COB_CA!$B$58))
A26: 22 | B26: =IF(COB_CA!$B$44=12,DATE(YEAR(COB_CA!$B$22)+INT((MONTH(COB_CA!$B$22)-1+21)/12),MOD(MONTH(COB_CA!$B$22)-1+21,12)+1,1)+(DAY(COB_CA!$B$22)-1),IF(COB_CA!$B$44=24,COB_CA!$B$22+ROUND((21*365.25)/24,0),IF(COB_CA!$B$44=26,COB_CA!$B$22+294,COB_CA!$B$22+147))) | C26: =G25 | D26: =IF((A26<=COB_CA!$B$58),ROUND(C26*COB_CA!$B$45,2),0) | E26: =IF((A26<=COB_CA!$B$58),IF(AND((A26<=COB_CA!$B$58),ROUND(C26-ROUND(COB_CA!$B$59-D26,2),2)<=0),C26,ROUND(COB_CA!$B$59-D26,2)),0) | F26: =IF((A26<=COB_CA!$B$58),IF(AND((A26<=COB_CA!$B$58),ROUND(C26-ROUND(COB_CA!$B$59-D26,2),2)<=0),ROUND(D26+E26,2),COB_CA!$B$59),0) | G26: =IF((A26<=COB_CA!$B$58),IF(AND((A26<=COB_CA!$B$58),ROUND(C26-ROUND(COB_CA!$B$59-D26,2),2)<=0),0,ROUND(C26-E26,2)),C26) | H26: =AND(H25,C25>0,(A26<=COB_CA!$B$58))
A27: 23 | B27: =IF(COB_CA!$B$44=12,DATE(YEAR(COB_CA!$B$22)+INT((MONTH(COB_CA!$B$22)-1+22)/12),MOD(MONTH(COB_CA!$B$22)-1+22,12)+1,1)+(DAY(COB_CA!$B$22)-1),IF(COB_CA!$B$44=24,COB_CA!$B$22+ROUND((22*365.25)/24,0),IF(COB_CA!$B$44=26,COB_CA!$B$22+308,COB_CA!$B$22+154))) | C27: =G26 | D27: =IF((A27<=COB_CA!$B$58),ROUND(C27*COB_CA!$B$45,2),0) | E27: =IF((A27<=COB_CA!$B$58),IF(AND((A27<=COB_CA!$B$58),ROUND(C27-ROUND(COB_CA!$B$59-D27,2),2)<=0),C27,ROUND(COB_CA!$B$59-D27,2)),0) | F27: =IF((A27<=COB_CA!$B$58),IF(AND((A27<=COB_CA!$B$58),ROUND(C27-ROUND(COB_CA!$B$59-D27,2),2)<=0),ROUND(D27+E27,2),COB_CA!$B$59),0) | G27: =IF((A27<=COB_CA!$B$58),IF(AND((A27<=COB_CA!$B$58),ROUND(C27-ROUND(COB_CA!$B$59-D27,2),2)<=0),0,ROUND(C27-E27,2)),C27) | H27: =AND(H26,C26>0,(A27<=COB_CA!$B$58))
A28: 24 | B28: =IF(COB_CA!$B$44=12,DATE(YEAR(COB_CA!$B$22)+INT((MONTH(COB_CA!$B$22)-1+23)/12),MOD(MONTH(COB_CA!$B$22)-1+23,12)+1,1)+(DAY(COB_CA!$B$22)-1),IF(COB_CA!$B$44=24,COB_CA!$B$22+ROUND((23*365.25)/24,0),IF(COB_CA!$B$44=26,COB_CA!$B$22+322,COB_CA!$B$22+161))) | C28: =G27 | D28: =IF((A28<=COB_CA!$B$58),ROUND(C28*COB_CA!$B$45,2),0) | E28: =IF((A28<=COB_CA!$B$58),IF(AND((A28<=COB_CA!$B$58),ROUND(C28-ROUND(COB_CA!$B$59-D28,2),2)<=0),C28,ROUND(COB_CA!$B$59-D28,2)),0) | F28: =IF((A28<=COB_CA!$B$58),IF(AND((A28<=COB_CA!$B$58),ROUND(C28-ROUND(COB_CA!$B$59-D28,2),2)<=0),ROUND(D28+E28,2),COB_CA!$B$59),0) | G28: =IF((A28<=COB_CA!$B$58),IF(AND((A28<=COB_CA!$B$58),ROUND(C28-ROUND(COB_CA!$B$59-D28,2),2)<=0),0,ROUND(C28-E28,2)),C28) | H28: =AND(H27,C27>0,(A28<=COB_CA!$B$58))
A29: 25 | B29: =IF(COB_CA!$B$44=12,DATE(YEAR(COB_CA!$B$22)+INT((MONTH(COB_CA!$B$22)-1+24)/12),MOD(MONTH(COB_CA!$B$22)-1+24,12)+1,1)+(DAY(COB_CA!$B$22)-1),IF(COB_CA!$B$44=24,COB_CA!$B$22+ROUND((24*365.25)/24,0),IF(COB_CA!$B$44=26,COB_CA!$B$22+336,COB_CA!$B$22+168))) | C29: =G28 | D29: =IF((A29<=COB_CA!$B$58),ROUND(C29*COB_CA!$B$45,2),0) | E29: =IF((A29<=COB_CA!$B$58),IF(AND((A29<=COB_CA!$B$58),ROUND(C29-ROUND(COB_CA!$B$59-D29,2),2)<=0),C29,ROUND(COB_CA!$B$59-D29,2)),0) | F29: =IF((A29<=COB_CA!$B$58),IF(AND((A29<=COB_CA!$B$58),ROUND(C29-ROUND(COB_CA!$B$59-D29,2),2)<=0),ROUND(D29+E29,2),COB_CA!$B$59),0) | G29: =IF((A29<=COB_CA!$B$58),IF(AND((A29<=COB_CA!$B$58),ROUND(C29-ROUND(COB_CA!$B$59-D29,2),2)<=0),0,ROUND(C29-E29,2)),C29) | H29: =AND(H28,C28>0,(A29<=COB_CA!$B$58))
A30: 26 | B30: =IF(COB_CA!$B$44=12,DATE(YEAR(COB_CA!$B$22)+INT((MONTH(COB_CA!$B$22)-1+25)/12),MOD(MONTH(COB_CA!$B$22)-1+25,12)+1,1)+(DAY(COB_CA!$B$22)-1),IF(COB_CA!$B$44=24,COB_CA!$B$22+ROUND((25*365.25)/24,0),IF(COB_CA!$B$44=26,COB_CA!$B$22+350,COB_CA!$B$22+175))) | C30: =G29 | D30: =IF((A30<=COB_CA!$B$58),ROUND(C30*COB_CA!$B$45,2),0) | E30: =IF((A30<=COB_CA!$B$58),IF(AND((A30<=COB_CA!$B$58),ROUND(C30-ROUND(COB_CA!$B$59-D30,2),2)<=0),C30,ROUND(COB_CA!$B$59-D30,2)),0) | F30: =IF((A30<=COB_CA!$B$58),IF(AND((A30<=COB_CA!$B$58),ROUND(C30-ROUND(COB_CA!$B$59-D30,2),2)<=0),ROUND(D30+E30,2),COB_CA!$B$59),0) | G30: =IF((A30<=COB_CA!$B$58),IF(AND((A30<=COB_CA!$B$58),ROUND(C30-ROUND(COB_CA!$B$59-D30,2),2)<=0),0,ROUND(C30-E30,2)),C30) | H30: =AND(H29,C29>0,(A30<=COB_CA!$B$58))
A31: 27 | B31: =IF(COB_CA!$B$44=12,DATE(YEAR(COB_CA!$B$22)+INT((MONTH(COB_CA!$B$22)-1+26)/12),MOD(MONTH(COB_CA!$B$22)-1+26,12)+1,1)+(DAY(COB_CA!$B$22)-1),IF(COB_CA!$B$44=24,COB_CA!$B$22+ROUND((26*365.25)/24,0),IF(COB_CA!$B$44=26,COB_CA!$B$22+364,COB_CA!$B$22+182))) | C31: =G30 | D31: =IF((A31<=COB_CA!$B$58),ROUND(C31*COB_CA!$B$45,2),0) | E31: =IF((A31<=COB_CA!$B$58),IF(AND((A31<=COB_CA!$B$58),ROUND(C31-ROUND(COB_CA!$B$59-D31,2),2)<=0),C31,ROUND(COB_CA!$B$59-D31,2)),0) | F31: =IF((A31<=COB_CA!$B$58),IF(AND((A31<=COB_CA!$B$58),ROUND(C31-ROUND(COB_CA!$B$59-D31,2),2)<=0),ROUND(D31+E31,2),COB_CA!$B$59),0) | G31: =IF((A31<=COB_CA!$B$58),IF(AND((A31<=COB_CA!$B$58),ROUND(C31-ROUND(COB_CA!$B$59-D31,2),2)<=0),0,ROUND(C31-E31,2)),C31) | H31: =AND(H30,C30>0,(A31<=COB_CA!$B$58))
A32: 28 | B32: =IF(COB_CA!$B$44=12,DATE(YEAR(COB_CA!$B$22)+INT((MONTH(COB_CA!$B$22)-1+27)/12),MOD(MONTH(COB_CA!$B$22)-1+27,12)+1,1)+(DAY(COB_CA!$B$22)-1),IF(COB_CA!$B$44=24,COB_CA!$B$22+ROUND((27*365.25)/24,0),IF(COB_CA!$B$44=26,COB_CA!$B$22+378,COB_CA!$B$22+189))) | C32: =G31 | D32: =IF((A32<=COB_CA!$B$58),ROUND(C32*COB_CA!$B$45,2),0) | E32: =IF((A32<=COB_CA!$B$58),IF(AND((A32<=COB_CA!$B$58),ROUND(C32-ROUND(COB_CA!$B$59-D32,2),2)<=0),C32,ROUND(COB_CA!$B$59-D32,2)),0) | F32: =IF((A32<=COB_CA!$B$58),IF(AND((A32<=COB_CA!$B$58),ROUND(C32-ROUND(COB_CA!$B$59-D32,2),2)<=0),ROUND(D32+E32,2),COB_CA!$B$59),0) | G32: =IF((A32<=COB_CA!$B$58),IF(AND((A32<=COB_CA!$B$58),ROUND(C32-ROUND(COB_CA!$B$59-D32,2),2)<=0),0,ROUND(C32-E32,2)),C32) | H32: =AND(H31,C31>0,(A32<=COB_CA!$B$58))
A33: 29 | B33: =IF(COB_CA!$B$44=12,DATE(YEAR(COB_CA!$B$22)+INT((MONTH(COB_CA!$B$22)-1+28)/12),MOD(MONTH(COB_CA!$B$22)-1+28,12)+1,1)+(DAY(COB_CA!$B$22)-1),IF(COB_CA!$B$44=24,COB_CA!$B$22+ROUND((28*365.25)/24,0),IF(COB_CA!$B$44=26,COB_CA!$B$22+392,COB_CA!$B$22+196))) | C33: =G32 | D33: =IF((A33<=COB_CA!$B$58),ROUND(C33*COB_CA!$B$45,2),0) | E33: =IF((A33<=COB_CA!$B$58),IF(AND((A33<=COB_CA!$B$58),ROUND(C33-ROUND(COB_CA!$B$59-D33,2),2)<=0),C33,ROUND(COB_CA!$B$59-D33,2)),0) | F33: =IF((A33<=COB_CA!$B$58),IF(AND((A33<=COB_CA!$B$58),ROUND(C33-ROUND(COB_CA!$B$59-D33,2),2)<=0),ROUND(D33+E33,2),COB_CA!$B$59),0) | G33: =IF((A33<=COB_CA!$B$58),IF(AND((A33<=COB_CA!$B$58),ROUND(C33-ROUND(COB_CA!$B$59-D33,2),2)<=0),0,ROUND(C33-E33,2)),C33) | H33: =AND(H32,C32>0,(A33<=COB_CA!$B$58))
A34: 30 | B34: =IF(COB_CA!$B$44=12,DATE(YEAR(COB_CA!$B$22)+INT((MONTH(COB_CA!$B$22)-1+29)/12),MOD(MONTH(COB_CA!$B$22)-1+29,12)+1,1)+(DAY(COB_CA!$B$22)-1),IF(COB_CA!$B$44=24,COB_CA!$B$22+ROUND((29*365.25)/24,0),IF(COB_CA!$B$44=26,COB_CA!$B$22+406,COB_CA!$B$22+203))) | C34: =G33 | D34: =IF((A34<=COB_CA!$B$58),ROUND(C34*COB_CA!$B$45,2),0) | E34: =IF((A34<=COB_CA!$B$58),IF(AND((A34<=COB_CA!$B$58),ROUND(C34-ROUND(COB_CA!$B$59-D34,2),2)<=0),C34,ROUND(COB_CA!$B$59-D34,2)),0) | F34: =IF((A34<=COB_CA!$B$58),IF(AND((A34<=COB_CA!$B$58),ROUND(C34-ROUND(COB_CA!$B$59-D34,2),2)<=0),ROUND(D34+E34,2),COB_CA!$B$59),0) | G34: =IF((A34<=COB_CA!$B$58),IF(AND((A34<=COB_CA!$B$58),ROUND(C34-ROUND(COB_CA!$B$59-D34,2),2)<=0),0,ROUND(C34-E34,2)),C34) | H34: =AND(H33,C33>0,(A34<=COB_CA!$B$58))
A35: 31 | B35: =IF(COB_CA!$B$44=12,DATE(YEAR(COB_CA!$B$22)+INT((MONTH(COB_CA!$B$22)-1+30)/12),MOD(MONTH(COB_CA!$B$22)-1+30,12)+1,1)+(DAY(COB_CA!$B$22)-1),IF(COB_CA!$B$44=24,COB_CA!$B$22+ROUND((30*365.25)/24,0),IF(COB_CA!$B$44=26,COB_CA!$B$22+420,COB_CA!$B$22+210))) | C35: =G34 | D35: =IF((A35<=COB_CA!$B$58),ROUND(C35*COB_CA!$B$45,2),0) | E35: =IF((A35<=COB_CA!$B$58),IF(AND((A35<=COB_CA!$B$58),ROUND(C35-ROUND(COB_CA!$B$59-D35,2),2)<=0),C35,ROUND(COB_CA!$B$59-D35,2)),0) | F35: =IF((A35<=COB_CA!$B$58),IF(AND((A35<=COB_CA!$B$58),ROUND(C35-ROUND(COB_CA!$B$59-D35,2),2)<=0),ROUND(D35+E35,2),COB_CA!$B$59),0) | G35: =IF((A35<=COB_CA!$B$58),IF(AND((A35<=COB_CA!$B$58),ROUND(C35-ROUND(COB_CA!$B$59-D35,2),2)<=0),0,ROUND(C35-E35,2)),C35) | H35: =AND(H34,C34>0,(A35<=COB_CA!$B$58))
A36: 32 | B36: =IF(COB_CA!$B$44=12,DATE(YEAR(COB_CA!$B$22)+INT((MONTH(COB_CA!$B$22)-1+31)/12),MOD(MONTH(COB_CA!$B$22)-1+31,12)+1,1)+(DAY(COB_CA!$B$22)-1),IF(COB_CA!$B$44=24,COB_CA!$B$22+ROUND((31*365.25)/24,0),IF(COB_CA!$B$44=26,COB_CA!$B$22+434,COB_CA!$B$22+217))) | C36: =G35 | D36: =IF((A36<=COB_CA!$B$58),ROUND(C36*COB_CA!$B$45,2),0) | E36: =IF((A36<=COB_CA!$B$58),IF(AND((A36<=COB_CA!$B$58),ROUND(C36-ROUND(COB_CA!$B$59-D36,2),2)<=0),C36,ROUND(COB_CA!$B$59-D36,2)),0) | F36: =IF((A36<=COB_CA!$B$58),IF(AND((A36<=COB_CA!$B$58),ROUND(C36-ROUND(COB_CA!$B$59-D36,2),2)<=0),ROUND(D36+E36,2),COB_CA!$B$59),0) | G36: =IF((A36<=COB_CA!$B$58),IF(AND((A36<=COB_CA!$B$58),ROUND(C36-ROUND(COB_CA!$B$59-D36,2),2)<=0),0,ROUND(C36-E36,2)),C36) | H36: =AND(H35,C35>0,(A36<=COB_CA!$B$58))
A37: 33 | B37: =IF(COB_CA!$B$44=12,DATE(YEAR(COB_CA!$B$22)+INT((MONTH(COB_CA!$B$22)-1+32)/12),MOD(MONTH(COB_CA!$B$22)-1+32,12)+1,1)+(DAY(COB_CA!$B$22)-1),IF(COB_CA!$B$44=24,COB_CA!$B$22+ROUND((32*365.25)/24,0),IF(COB_CA!$B$44=26,COB_CA!$B$22+448,COB_CA!$B$22+224))) | C37: =G36 | D37: =IF((A37<=COB_CA!$B$58),ROUND(C37*COB_CA!$B$45,2),0) | E37: =IF((A37<=COB_CA!$B$58),IF(AND((A37<=COB_CA!$B$58),ROUND(C37-ROUND(COB_CA!$B$59-D37,2),2)<=0),C37,ROUND(COB_CA!$B$59-D37,2)),0) | F37: =IF((A37<=COB_CA!$B$58),IF(AND((A37<=COB_CA!$B$58),ROUND(C37-ROUND(COB_CA!$B$59-D37,2),2)<=0),ROUND(D37+E37,2),COB_CA!$B$59),0) | G37: =IF((A37<=COB_CA!$B$58),IF(AND((A37<=COB_CA!$B$58),ROUND(C37-ROUND(COB_CA!$B$59-D37,2),2)<=0),0,ROUND(C37-E37,2)),C37) | H37: =AND(H36,C36>0,(A37<=COB_CA!$B$58))
A38: 34 | B38: =IF(COB_CA!$B$44=12,DATE(YEAR(COB_CA!$B$22)+INT((MONTH(COB_CA!$B$22)-1+33)/12),MOD(MONTH(COB_CA!$B$22)-1+33,12)+1,1)+(DAY(COB_CA!$B$22)-1),IF(COB_CA!$B$44=24,COB_CA!$B$22+ROUND((33*365.25)/24,0),IF(COB_CA!$B$44=26,COB_CA!$B$22+462,COB_CA!$B$22+231))) | C38: =G37 | D38: =IF((A38<=COB_CA!$B$58),ROUND(C38*COB_CA!$B$45,2),0) | E38: =IF((A38<=COB_CA!$B$58),IF(AND((A38<=COB_CA!$B$58),ROUND(C38-ROUND(COB_CA!$B$59-D38,2),2)<=0),C38,ROUND(COB_CA!$B$59-D38,2)),0) | F38: =IF((A38<=COB_CA!$B$58),IF(AND((A38<=COB_CA!$B$58),ROUND(C38-ROUND(COB_CA!$B$59-D38,2),2)<=0),ROUND(D38+E38,2),COB_CA!$B$59),0) | G38: =IF((A38<=COB_CA!$B$58),IF(AND((A38<=COB_CA!$B$58),ROUND(C38-ROUND(COB_CA!$B$59-D38,2),2)<=0),0,ROUND(C38-E38,2)),C38) | H38: =AND(H37,C37>0,(A38<=COB_CA!$B$58))
A39: 35 | B39: =IF(COB_CA!$B$44=12,DATE(YEAR(COB_CA!$B$22)+INT((MONTH(COB_CA!$B$22)-1+34)/12),MOD(MONTH(COB_CA!$B$22)-1+34,12)+1,1)+(DAY(COB_CA!$B$22)-1),IF(COB_CA!$B$44=24,COB_CA!$B$22+ROUND((34*365.25)/24,0),IF(COB_CA!$B$44=26,COB_CA!$B$22+476,COB_CA!$B$22+238))) | C39: =G38 | D39: =IF((A39<=COB_CA!$B$58),ROUND(C39*COB_CA!$B$45,2),0) | E39: =IF((A39<=COB_CA!$B$58),IF(AND((A39<=COB_CA!$B$58),ROUND(C39-ROUND(COB_CA!$B$59-D39,2),2)<=0),C39,ROUND(COB_CA!$B$59-D39,2)),0) | F39: =IF((A39<=COB_CA!$B$58),IF(AND((A39<=COB_CA!$B$58),ROUND(C39-ROUND(COB_CA!$B$59-D39,2),2)<=0),ROUND(D39+E39,2),COB_CA!$B$59),0) | G39: =IF((A39<=COB_CA!$B$58),IF(AND((A39<=COB_CA!$B$58),ROUND(C39-ROUND(COB_CA!$B$59-D39,2),2)<=0),0,ROUND(C39-E39,2)),C39) | H39: =AND(H38,C38>0,(A39<=COB_CA!$B$58))
A40: 36 | B40: =IF(COB_CA!$B$44=12,DATE(YEAR(COB_CA!$B$22)+INT((MONTH(COB_CA!$B$22)-1+35)/12),MOD(MONTH(COB_CA!$B$22)-1+35,12)+1,1)+(DAY(COB_CA!$B$22)-1),IF(COB_CA!$B$44=24,COB_CA!$B$22+ROUND((35*365.25)/24,0),IF(COB_CA!$B$44=26,COB_CA!$B$22+490,COB_CA!$B$22+245))) | C40: =G39 | D40: =IF((A40<=COB_CA!$B$58),ROUND(C40*COB_CA!$B$45,2),0) | E40: =IF((A40<=COB_CA!$B$58),IF(AND((A40<=COB_CA!$B$58),ROUND(C40-ROUND(COB_CA!$B$59-D40,2),2)<=0),C40,ROUND(COB_CA!$B$59-D40,2)),0) | F40: =IF((A40<=COB_CA!$B$58),IF(AND((A40<=COB_CA!$B$58),ROUND(C40-ROUND(COB_CA!$B$59-D40,2),2)<=0),ROUND(D40+E40,2),COB_CA!$B$59),0) | G40: =IF((A40<=COB_CA!$B$58),IF(AND((A40<=COB_CA!$B$58),ROUND(C40-ROUND(COB_CA!$B$59-D40,2),2)<=0),0,ROUND(C40-E40,2)),C40) | H40: =AND(H39,C39>0,(A40<=COB_CA!$B$58))
A41: 37 | B41: =IF(COB_CA!$B$44=12,DATE(YEAR(COB_CA!$B$22)+INT((MONTH(COB_CA!$B$22)-1+36)/12),MOD(MONTH(COB_CA!$B$22)-1+36,12)+1,1)+(DAY(COB_CA!$B$22)-1),IF(COB_CA!$B$44=24,COB_CA!$B$22+ROUND((36*365.25)/24,0),IF(COB_CA!$B$44=26,COB_CA!$B$22+504,COB_CA!$B$22+252))) | C41: =G40 | D41: =IF((A41<=COB_CA!$B$58),ROUND(C41*COB_CA!$B$45,2),0) | E41: =IF((A41<=COB_CA!$B$58),IF(AND((A41<=COB_CA!$B$58),ROUND(C41-ROUND(COB_CA!$B$59-D41,2),2)<=0),C41,ROUND(COB_CA!$B$59-D41,2)),0) | F41: =IF((A41<=COB_CA!$B$58),IF(AND((A41<=COB_CA!$B$58),ROUND(C41-ROUND(COB_CA!$B$59-D41,2),2)<=0),ROUND(D41+E41,2),COB_CA!$B$59),0) | G41: =IF((A41<=COB_CA!$B$58),IF(AND((A41<=COB_CA!$B$58),ROUND(C41-ROUND(COB_CA!$B$59-D41,2),2)<=0),0,ROUND(C41-E41,2)),C41) | H41: =AND(H40,C40>0,(A41<=COB_CA!$B$58))
...
