Workbook

Sheet README
A1: COB Calculator (Excel)
A2: A formula-driven Excel port of the COB segmented mortgage / cost-of-borrowing engine.
A5: COLOR LEGEND
A6: Blue text, yellow-tinted cells = INPUT -- edit these.
A7: Black text = COMPUTED formula -- do not edit; it will recalculate automatically.
A9: SHEETS
A10: Segments, LumpSums, Overrides, PMI_Costs -- inputs for the segmented mortgage engine.
A11: Schedule, Summary, YearlySummary -- computed output of the segmented engine (do not edit).
A12: PaymentFrequency, ExtraPayment -- standalone single-loan calculators (own inputs).
A13: Points, Refinance, CompareTerms, LTV_DSCR, ARM_Reset, Fees_APR, DTI_Affordability -- standalone calculators.
A15: KEY ASSUMPTIONS (see docs/new-req/ in the source repo for full specs)
A16: - Segmented Schedule is bounded to 360 rows (30 years monthly). Extend by selecting the
... A33: for details. Recalculated with LibreOffice via the xlsx skill's recalc.py: 0 formula errors.

Sheet Segments
A1: Segments (input)
A2: Blue cells = edit these. One row per segment, chronological. Segment 1's Starting Balance is required; later segments inherit their starting balance from the prior segment's computed ending balance (do not fill in Starting Balance for row 2+).
A4: Seg # | B4: Start Date | C4: Annual Rate % | D4: Payment Amount (blank = compute) | E4: Amortization Months Remaining (blank if Payment Amount given) | F4: Term Months (blank = final/runs to payoff) | G4: Starting Balance (segment 1 only) | H4: Balloon? (Y/N) | I4: Interest Only? (Y/N) | J4: Start Payment # | K4: End Payment # | L4: Monthly Payment (computed) | M4: Segment Starting Balance (computed) | N4: Segment Ending Balance (computed)
A5: 1 | B5: 2024-01-01 | C5: 5 | E5: 300 | F5: 60 | G5: 200000 | H5: N | I5: N | J5: =1 | K5: =IF(OR($F5="",$J5=""),"",J5+F5-1) | L5: =IF($B5="","",IF(I5="Y",ROUND(M5*(C5/100/12),2),IF(D5<>"",ROUND(D5,2),ROUND(-PMT(C5/100/12,E5,M5),2)))) | M5: =G5 | N5: =IF($B5="","",IF(K5<>"",IFERROR(INDEX(Schedule!$AA:$AA,MATCH(K5,Schedule!$A:$A,0)),""),IFERROR(INDEX(Schedule!$AA:$AA,MATCH(SUMPRODUCT(MAX((Schedule!$B$5:$B$364=$A5)*Schedule!$A$5:$A$364)),Schedule!$A:$A,0)),"")))
A6: 2 | B6: 2029-01-01 | C6: 6 | E6: 240 | H6: N | I6: N | J6: =IF($F5="","",K5+1) | K6: =IF(OR($F6="",$J6=""),"",J6+F6-1) | L6: =IF($B6="","",IF(I6="Y",ROUND(M6*(C6/100/12),2),IF(D6<>"",ROUND(D6,2),ROUND(-PMT(C6/100/12,E6,M6),2)))) | M6: =IF($B6="","",IFERROR(INDEX(Schedule!$AA:$AA,MATCH(K5,Schedule!$A:$A,0)),"")) | N6: =IF($B6="","",IF(K6<>"",IFERROR(INDEX(Schedule!$AA:$AA,MATCH(K6,Schedule!$A:$A,0)),""),IFERROR(INDEX(Schedule!$AA:$AA,MATCH(SUMPRODUCT(MAX((Schedule!$B$5:$B$364=$A6)*Schedule!$A$5:$A$364)),Schedule!$A:$A,0)),"")))
A7: 3 | J7: =IF($F6="","",K6+1) | K7: =IF(OR($F7="",$J7=""),"",J7+F7-1) | L7: =IF($B7="","",IF(I7="Y",ROUND(M7*(C7/100/12),2),IF(D7<>"",ROUND(D7,2),ROUND(-PMT(C7/100/12,E7,M7),2)))) | M7: =IF($B7="","",IFERROR(INDEX(Schedule!$AA:$AA,MATCH(K6,Schedule!$A:$A,0)),"")) | N7: =IF($B7="","",IF(K7<>"",IFERROR(INDEX(Schedule!$AA:$AA,MATCH(K7,Schedule!$A:$A,0)),""),IFERROR(INDEX(Schedule!$AA:$AA,MATCH(SUMPRODUCT(MAX((Schedule!$B$5:$B$364=$A7)*Schedule!$A$5:$A$364)),Schedule!$A:$A,0)),"")))
A8: 4 | J8: =IF($F7="","",K7+1) | K8: =IF(OR($F8="",$J8=""),"",J8+F8-1) | L8: =IF($B8="","",IF(I8="Y",ROUND(M8*(C8/100/12),2),IF(D8<>"",ROUND(D8,2),ROUND(-PMT(C8/100/12,E8,M8),2)))) | M8: =IF($B8="","",IFERROR(INDEX(Schedule!$AA:$AA,MATCH(K7,Schedule!$A:$A,0)),"")) | N8: =IF($B8="","",IF(K8<>"",IFERROR(INDEX(Schedule!$AA:$AA,MATCH(K8,Schedule!$A:$A,0)),""),IFERROR(INDEX(Schedule!$AA:$AA,MATCH(SUMPRODUCT(MAX((Schedule!$B$5:$B$364=$A8)*Schedule!$A$5:$A$364)),Schedule!$A:$A,0)),"")))
A9: 5 | J9: =IF($F8="","",K8+1) | K9: =IF(OR($F9="",$J9=""),"",J9+F9-1) | L9: =IF($B9="","",IF(I9="Y",ROUND(M9*(C9/100/12),2),IF(D9<>"",ROUND(D9,2),ROUND(-PMT(C9/100/12,E9,M9),2)))) | M9: =IF($B9="","",IFERROR(INDEX(Schedule!$AA:$AA,MATCH(K8,Schedule!$A:$A,0)),"")) | N9: =IF($B9="","",IF(K9<>"",IFERROR(INDEX(Schedule!$AA:$AA,MATCH(K9,Schedule!$A:$A,0)),""),IFERROR(INDEX(Schedule!$AA:$AA,MATCH(SUMPRODUCT(MAX((Schedule!$B$5:$B$364=$A9)*Schedule!$A$5:$A$364)),Schedule!$A:$A,0)),"")))
A10: 6 | J10: =IF($F9="","",K9+1) | K10: =IF(OR($F10="",$J10=""),"",J10+F10-1) | L10: =IF($B10="","",IF(I10="Y",ROUND(M10*(C10/100/12),2),IF(D10<>"",ROUND(D10,2),ROUND(-PMT(C10/100/12,E10,M10),2)))) | M10: =IF($B10="","",IFERROR(INDEX(Schedule!$AA:$AA,MATCH(K9,Schedule!$A:$A,0)),"")) | N10: =IF($B10="","",IF(K10<>"",IFERROR(INDEX(Schedule!$AA:$AA,MATCH(K10,Schedule!$A:$A,0)),""),IFERROR(INDEX(Schedule!$AA:$AA,MATCH(SUMPRODUCT(MAX((Schedule!$B$5:$B$364=$A10)*Schedule!$A$5:$A$364)),Schedule!$A:$A,0)),"")))
A11: 7 | J11: =IF($F10="","",K10+1) | K11: =IF(OR($F11="",$J11=""),"",J11+F11-1) | L11: =IF($B11="","",IF(I11="Y",ROUND(M11*(C11/100/12),2),IF(D11<>"",ROUND(D11,2),ROUND(-PMT(C11/100/12,E11,M11),2)))) | M11: =IF($B11="","",IFERROR(INDEX(Schedule!$AA:$AA,MATCH(K10,Schedule!$A:$A,0)),"")) | N11: =IF($B11="","",IF(K11<>"",IFERROR(INDEX(Schedule!$AA:$AA,MATCH(K11,Schedule!$A:$A,0)),""),IFERROR(INDEX(Schedule!$AA:$AA,MATCH(SUMPRODUCT(MAX((Schedule!$B$5:$B$364=$A11)*Schedule!$A$5:$A$364)),Schedule!$A:$A,0)),"")))
A12: 8 | J12: =IF($F11="","",K11+1) | K12: =IF(OR($F12="",$J12=""),"",J12+F12-1) | L12: =IF($B12="","",IF(I12="Y",ROUND(M12*(C12/100/12),2),IF(D12<>"",ROUND(D12,2),ROUND(-PMT(C12/100/12,E12,M12),2)))) | M12: =IF($B12="","",IFERROR(INDEX(Schedule!$AA:$AA,MATCH(K11,Schedule!$A:$A,0)),"")) | N12: =IF($B12="","",IF(K12<>"",IFERROR(INDEX(Schedule!$AA:$AA,MATCH(K12,Schedule!$A:$A,0)),""),IFERROR(INDEX(Schedule!$AA:$AA,MATCH(SUMPRODUCT(MAX((Schedule!$B$5:$B$364=$A12)*Schedule!$A$5:$A$364)),Schedule!$A:$A,0)),"")))

Sheet LumpSums
A1: Lump Sum Payments (input)
A2: Applied at a segment/renewal boundary only -- After Payment # must equal one of Segments!K (End Payment #) for a non-final segment. Leave rows blank if unused.
A4: After Payment # | B4: Amount
A5: 60 | B5: 20000

Sheet Overrides
A1: Manual Payment Overrides (input)
A2: Bank-statement reconciliation rows. Leave a field blank to use the computed value; Payment # is required, all other fields optional per row.
A4: Payment # | B4: Payment Amount | C4: Interest Portion | D4: Principal Portion | E4: Remaining Balance | F4: Reason
A5: 10 | C5: 700 | F5: example: bank fee adjustment

Sheet PMI_Costs
A1: PMI & Recurring Costs (input)
A2: Leave PMI/cost annual amounts blank (0) to disable that cost.
A4: PMI annual rate (%) | B4: 0.6
A5: Property value ($) | B5: 220000
A6: PMI drop-at LTV (%) | B6: 80
A8: Property tax annual amount ($) | B8: 4800
A9: Property tax annual increase (%) | B9: 0
A10: Home insurance annual amount ($) | B10: 1200
A11: Home insurance annual increase (%) | B11: 0
A12: HOA annual amount ($) | B12: 0
A13: HOA annual increase (%) | B13: 0

Sheet Schedule
A1: Schedule (computed) -- do not edit
A2: One row per global payment number, 1..360 (30 years). Rows past the loan's actual payoff show as blank. Extend by selecting the last row and copying its formulas down if you need a longer schedule.
A4: Payment # | B4: Seg Idx | C4: Seg Start Date | D4: Seg Start Pay# | E4: Payment Date | F4: Monthly Rate | G4: Seg Monthly Pmt | H4: Seg IO? | I4: Seg Final? | J4: Seg End Pay# | K4: Seg Known Len | L4: Beginning Balance | M4: Ovr: Interest | N4: Ovr: Rem Bal | O4: Ovr: Principal | P4: Ovr: Payment | Q4: Ovr: Reason | R4: Has Override? | S4: Payoff Row? | T4: Interest | U4: Principal (pre-lump) | V4: Payment (pre-lump) | W4: Ending Bal (pre-lump) | X4: Lump Sum Applied | Y4: Principal | Z4: Payment | AA4: Ending Balance | AB4: Active Row? | AC4: Tax | AD4: Insurance | AE4: HOA | AF4: Current LTV | AG4: PMI Active? | AH4: PMI | AI4: PMI Just Dropped?
A5: 1 | B5: =SUMPRODUCT((Segments!$J$5:$J$12<>"")*(Segments!$J$5:$J$12<=A5)) | C5: =INDEX(Segments!$B$5:$B$12,B5) | D5: =INDEX(Segments!$J$5:$J$12,B5) | E5: =DATE(YEAR(C5)+INT((MONTH(C5)-1+(A5-D5))/12),MOD(MONTH(C5)-1+(A5-D5),12)+1,1)+(DAY(C5)-1) | F5: =INDEX(Segments!$C$5:$C$12,B5)/100/12 | G5: =INDEX(Segments!$L$5:$L$12,B5) | H5: =INDEX(Segments!$I$5:$I$12,B5)="Y" | I5: =INDEX(Segments!$F$5:$F$12,B5)="" | J5: =INDEX(Segments!$K$5:$K$12,B5) | K5: =IF(INDEX(Segments!$F$5:$F$12,B5)<>"",INDEX(Segments!$F$5:$F$12,B5),IF(INDEX(Segments!$E$5:$E$12,B5)<>"",INDEX(Segments!$E$5:$E$12,B5),"")) | L5: =Segments!$G$5 | M5: =IFERROR(INDEX(Overrides!$C:$C,MATCH(A5,Overrides!$A:$A,0)),"") | N5: =IFERROR(INDEX(Overrides!$E:$E,MATCH(A5,Overrides!$A:$A,0)),"") | O5: =IFERROR(INDEX(Overrides!$D:$D,MATCH(A5,Overrides!$A:$A,0)),"") | P5: =IFERROR(INDEX(Overrides!$B:$B,MATCH(A5,Overrides!$A:$A,0)),"") | Q5: =IFERROR(INDEX(Overrides!$F:$F,MATCH(A5,Overrides!$A:$A,0)),"") | R5: =ISNUMBER(MATCH(A5,Overrides!$A:$A,0)) | S5: =OR(ROUND(L5-ROUND(G5-T5,2),2)<=0,AND(I5,K5<>"",(A5-D5+1)=K5)) | T5: =IF(M5<>"",M5,ROUND(L5*F5,2)) | U5: =IF(R5,IF(O5<>"",O5,IF(N5<>"",ROUND(L5-N5,2),ROUND((IF(P5<>"",P5,G5))-T5,2))),IF(H5,0,IF(S5,L5,ROUND(G5-T5,2)))) | V5: =IF(R5,IF(P5<>"",P5,ROUND(T5+U5,2)),IF(H5,T5,IF(S5,ROUND(T5+U5,2),G5))) | W5: =IF(R5,IF(N5<>"",N5,ROUND(L5-U5,2)),IF(H5,L5,IF(S5,0,ROUND(L5-U5,2)))) | X5: =IFERROR(MIN(INDEX(LumpSums!$B:$B,MATCH(A5,LumpSums!$A:$A,0)),W5),0) | Y5: =ROUND(U5+X5,2) | Z5: =ROUND(V5+X5,2) | AA5: =ROUND(W5-X5,2) | AB5: =TRUE | AC5: =IF(PMI_Costs!$B$8=0,0,ROUND(PMI_Costs!$B$8*(1+PMI_Costs!$B$9/100)^INT((A5-1)/12)/12,2)) | AD5: =IF(PMI_Costs!$B$10=0,0,ROUND(PMI_Costs!$B$10*(1+PMI_Costs!$B$11/100)^INT((A5-1)/12)/12,2)) | AE5: =IF(PMI_Costs!$B$12=0,0,ROUND(PMI_Costs!$B$12*(1+PMI_Costs!$B$13/100)^INT((A5-1)/12)/12,2)) | AF5: =IF(PMI_Costs!$B$5=0,0,AA5/PMI_Costs!$B$5) | AG5: =AND(PMI_Costs!$B$4>0,AF5>PMI_Costs!$B$6/100) | AH5: =IF(AG5,ROUND(Segments!$G$5*PMI_Costs!$B$4/100/12,2),0) | AI5: =FALSE
A6: 2 | B6: =SUMPRODUCT((Segments!$J$5:$J$12<>"")*(Segments!$J$5:$J$12<=A6)) | C6: =INDEX(Segments!$B$5:$B$12,B6) | D6: =INDEX(Segments!$J$5:$J$12,B6) | E6: =DATE(YEAR(C6)+INT((MONTH(C6)-1+(A6-D6))/12),MOD(MONTH(C6)-1+(A6-D6),12)+1,1)+(DAY(C6)-1) | F6: =INDEX(Segments!$C$5:$C$12,B6)/100/12 | G6: =INDEX(Segments!$L$5:$L$12,B6) | H6: =INDEX(Segments!$I$5:$I$12,B6)="Y" | I6: =INDEX(Segments!$F$5:$F$12,B6)="" | J6: =INDEX(Segments!$K$5:$K$12,B6) | K6: =IF(INDEX(Segments!$F$5:$F$12,B6)<>"",INDEX(Segments!$F$5:$F$12,B6),IF(INDEX(Segments!$E$5:$E$12,B6)<>"",INDEX(Segments!$E$5:$E$12,B6),"")) | L6: =AA5 | M6: =IFERROR(INDEX(Overrides!$C:$C,MATCH(A6,Overrides!$A:$A,0)),"") | N6: =IFERROR(INDEX(Overrides!$E:$E,MATCH(A6,Overrides!$A:$A,0)),"") | O6: =IFERROR(INDEX(Overrides!$D:$D,MATCH(A6,Overrides!$A:$A,0)),"") | P6: =IFERROR(INDEX(Overrides!$B:$B,MATCH(A6,Overrides!$A:$A,0)),"") | Q6: =IFERROR(INDEX(Overrides!$F:$F,MATCH(A6,Overrides!$A:$A,0)),"") | R6: =ISNUMBER(MATCH(A6,Overrides!$A:$A,0)) | S6: =OR(ROUND(L6-ROUND(G6-T6,2),2)<=0,AND(I6,K6<>"",(A6-D6+1)=K6)) | T6: =IF(M6<>"",M6,ROUND(L6*F6,2)) | U6: =IF(R6,IF(O6<>"",O6,IF(N6<>"",ROUND(L6-N6,2),ROUND((IF(P6<>"",P6,G6))-T6,2))),IF(H6,0,IF(S6,L6,ROUND(G6-T6,2)))) | V6: =IF(R6,IF(P6<>"",P6,ROUND(T6+U6,2)),IF(H6,T6,IF(S6,ROUND(T6+U6,2),G6))) | W6: =IF(R6,IF(N6<>"",N6,ROUND(L6-U6,2)),IF(H6,L6,IF(S6,0,ROUND(L6-U6,2)))) | X6: =IFERROR(MIN(INDEX(LumpSums!$B:$B,MATCH(A6,LumpSums!$A:$A,0)),W6),0) | Y6: =ROUND(U6+X6,2) | Z6: =ROUND(V6+X6,2) | AA6: =ROUND(W6-X6,2) | AB6: =AND(AB5,L6>0) | AC6: =IF(PMI_Costs!$B$8=0,0,ROUND(PMI_Costs!$B$8*(1+PMI_Costs!$B$9/100)^INT((A6-1)/12)/12,2)) | AD6: =IF(PMI_Costs!$B$10=0,0,ROUND(PMI_Costs!$B$10*(1+PMI_Costs!$B$11/100)^INT((A6-1)/12)/12,2)) | AE6: =IF(PMI_Costs!$B$12=0,0,ROUND(PMI_Costs!$B$12*(1+PMI_Costs!$B$13/100)^INT((A6-1)/12)/12,2)) | AF6: =IF(PMI_Costs!$B$5=0,0,AA6/PMI_Costs!$B$5) | AG6: =AND(PMI_Costs!$B$4>0,AF6>PMI_Costs!$B$6/100) | AH6: =IF(AG6,ROUND(Segments!$G$5*PMI_Costs!$B$4/100/12,2),0) | AI6: =AND(NOT(AG6),AG5)
A7: 3 | B7: =SUMPRODUCT((Segments!$J$5:$J$12<>"")*(Segments!$J$5:$J$12<=A7)) | C7: =INDEX(Segments!$B$5:$B$12,B7) | D7: =INDEX(Segments!$J$5:$J$12,B7) | E7: =DATE(YEAR(C7)+INT((MONTH(C7)-1+(A7-D7))/12),MOD(MONTH(C7)-1+(A7-D7),12)+1,1)+(DAY(C7)-1) | F7: =INDEX(Segments!$C$5:$C$12,B7)/100/12 | G7: =INDEX(Segments!$L$5:$L$12,B7) | H7: =INDEX(Segments!$I$5:$I$12,B7)="Y" | I7: =INDEX(Segments!$F$5:$F$12,B7)="" | J7: =INDEX(Segments!$K$5:$K$12,B7) | K7: =IF(INDEX(Segments!$F$5:$F$12,B7)<>"",INDEX(Segments!$F$5:$F$12,B7),IF(INDEX(Segments!$E$5:$E$12,B7)<>"",INDEX(Segments!$E$5:$E$12,B7),"")) | L7: =AA6 | M7: =IFERROR(INDEX(Overrides!$C:$C,MATCH(A7,Overrides!$A:$A,0)),"") | N7: =IFERROR(INDEX(Overrides!$E:$E,MATCH(A7,Overrides!$A:$A,0)),"") | O7: =IFERROR(INDEX(Overrides!$D:$D,MATCH(A7,Overrides!$A:$A,0)),"") | P7: =IFERROR(INDEX(Overrides!$B:$B,MATCH(A7,Overrides!$A:$A,0)),"") | Q7: =IFERROR(INDEX(Overrides!$F:$F,MATCH(A7,Overrides!$A:$A,0)),"") | R7: =ISNUMBER(MATCH(A7,Overrides!$A:$A,0)) | S7: =OR(ROUND(L7-ROUND(G7-T7,2),2)<=0,AND(I7,K7<>"",(A7-D7+1)=K7)) | T7: =IF(M7<>"",M7,ROUND(L7*F7,2)) | U7: =IF(R7,IF(O7<>"",O7,IF(N7<>"",ROUND(L7-N7,2),ROUND((IF(P7<>"",P7,G7))-T7,2))),IF(H7,0,IF(S7,L7,ROUND(G7-T7,2)))) | V7: =IF(R7,IF(P7<>"",P7,ROUND(T7+U7,2)),IF(H7,T7,IF(S7,ROUND(T7+U7,2),G7))) | W7: =IF(R7,IF(N7<>"",N7,ROUND(L7-U7,2)),IF(H7,L7,IF(S7,0,ROUND(L7-U7,2)))) | X7: =IFERROR(MIN(INDEX(LumpSums!$B:$B,MATCH(A7,LumpSums!$A:$A,0)),W7),0) | Y7: =ROUND(U7+X7,2) | Z7: =ROUND(V7+X7,2) | AA7: =ROUND(W7-X7,2) | AB7: =AND(AB6,L7>0) | AC7: =IF(PMI_Costs!$B$8=0,0,ROUND(PMI_Costs!$B$8*(1+PMI_Costs!$B$9/100)^INT((A7-1)/12)/12,2)) | AD7: =IF(PMI_Costs!$B$10=0,0,ROUND(PMI_Costs!$B$10*(1+PMI_Costs!$B$11/100)^INT((A7-1)/12)/12,2)) | AE7: =IF(PMI_Costs!$B$12=0,0,ROUND(PMI_Costs!$B$12*(1+PMI_Costs!$B$13/100)^INT((A7-1)/12)/12,2)) | AF7: =IF(PMI_Costs!$B$5=0,0,AA7/PMI_Costs!$B$5) | AG7: =AND(PMI_Costs!$B$4>0,AF7>PMI_Costs!$B$6/100) | AH7: =IF(AG7,ROUND(Segments!$G$5*PMI_Costs!$B$4/100/12,2),0) | AI7: =AND(NOT(AG7),AG6)
A8: 4 | B8: =SUMPRODUCT((Segments!$J$5:$J$12<>"")*(Segments!$J$5:$J$12<=A8)) | C8: =INDEX(Segments!$B$5:$B$12,B8) | D8: =INDEX(Segments!$J$5:$J$12,B8) | E8: =DATE(YEAR(C8)+INT((MONTH(C8)-1+(A8-D8))/12),MOD(MONTH(C8)-1+(A8-D8),12)+1,1)+(DAY(C8)-1) | F8: =INDEX(Segments!$C$5:$C$12,B8)/100/12 | G8: =INDEX(Segments!$L$5:$L$12,B8) | H8: =INDEX(Segments!$I$5:$I$12,B8)="Y" | I8: =INDEX(Segments!$F$5:$F$12,B8)="" | J8: =INDEX(Segments!$K$5:$K$12,B8) | K8: =IF(INDEX(Segments!$F$5:$F$12,B8)<>"",INDEX(Segments!$F$5:$F$12,B8),IF(INDEX(Segments!$E$5:$E$12,B8)<>"",INDEX(Segments!$E$5:$E$12,B8),"")) | L8: =AA7 | M8: =IFERROR(INDEX(Overrides!$C:$C,MATCH(A8,Overrides!$A:$A,0)),"") | N8: =IFERROR(INDEX(Overrides!$E:$E,MATCH(A8,Overrides!$A:$A,0)),"") | O8: =IFERROR(INDEX(Overrides!$D:$D,MATCH(A8,Overrides!$A:$A,0)),"") | P8: =IFERROR(INDEX(Overrides!$B:$B,MATCH(A8,Overrides!$A:$A,0)),"") | Q8: =IFERROR(INDEX(Overrides!$F:$F,MATCH(A8,Overrides!$A:$A,0)),"") | R8: =ISNUMBER(MATCH(A8,Overrides!$A:$A,0)) | S8: =OR(ROUND(L8-ROUND(G8-T8,2),2)<=0,AND(I8,K8<>"",(A8-D8+1)=K8)) | T8: =IF(M8<>"",M8,ROUND(L8*F8,2)) | U8: =IF(R8,IF(O8<>"",O8,IF(N8<>"",ROUND(L8-N8,2),ROUND((IF(P8<>"",P8,G8))-T8,2))),IF(H8,0,IF(S8,L8,ROUND(G8-T8,2)))) | V8: =IF(R8,IF(P8<>"",P8,ROUND(T8+U8,2)),IF(H8,T8,IF(S8,ROUND(T8+U8,2),G8))) | W8: =IF(R8,IF(N8<>"",N8,ROUND(L8-U8,2)),IF(H8,L8,IF(S8,0,ROUND(L8-U8,2)))) | X8: =IFERROR(MIN(INDEX(LumpSums!$B:$B,MATCH(A8,LumpSums!$A:$A,0)),W8),0) | Y8: =ROUND(U8+X8,2) | Z8: =ROUND(V8+X8,2) | AA8: =ROUND(W8-X8,2) | AB8: =AND(AB7,L8>0) | AC8: =IF(PMI_Costs!$B$8=0,0,ROUND(PMI_Costs!$B$8*(1+PMI_Costs!$B$9/100)^INT((A8-1)/12)/12,2)) | AD8: =IF(PMI_Costs!$B$10=0,0,ROUND(PMI_Costs!$B$10*(1+PMI_Costs!$B$11/100)^INT((A8-1)/12)/12,2)) | AE8: =IF(PMI_Costs!$B$12=0,0,ROUND(PMI_Costs!$B$12*(1+PMI_Costs!$B$13/100)^INT((A8-1)/12)/12,2)) | AF8: =IF(PMI_Costs!$B$5=0,0,AA8/PMI_Costs!$B$5) | AG8: =AND(PMI_Costs!$B$4>0,AF8>PMI_Costs!$B$6/100) | AH8: =IF(AG8,ROUND(Segments!$G$5*PMI_Costs!$B$4/100/12,2),0) | AI8: =AND(NOT(AG8),AG7)
A9: 5 | B9: =SUMPRODUCT((Segments!$J$5:$J$12<>"")*(Segments!$J$5:$J$12<=A9)) | C9: =INDEX(Segments!$B$5:$B$12,B9) | D9: =INDEX(Segments!$J$5:$J$12,B9) | E9: =DATE(YEAR(C9)+INT((MONTH(C9)-1+(A9-D9))/12),MOD(MONTH(C9)-1+(A9-D9),12)+1,1)+(DAY(C9)-1) | F9: =INDEX(Segments!$C$5:$C$12,B9)/100/12 | G9: =INDEX(Segments!$L$5:$L$12,B9) | H9: =INDEX(Segments!$I$5:$I$12,B9)="Y" | I9: =INDEX(Segments!$F$5:$F$12,B9)="" | J9: =INDEX(Segments!$K$5:$K$12,B9) | K9: =IF(INDEX(Segments!$F$5:$F$12,B9)<>"",INDEX(Segments!$F$5:$F$12,B9),IF(INDEX(Segments!$E$5:$E$12,B9)<>"",INDEX(Segments!$E$5:$E$12,B9),"")) | L9: =AA8 | M9: =IFERROR(INDEX(Overrides!$C:$C,MATCH(A9,Overrides!$A:$A,0)),"") | N9: =IFERROR(INDEX(Overrides!$E:$E,MATCH(A9,Overrides!$A:$A,0)),"") | O9: =IFERROR(INDEX(Overrides!$D:$D,MATCH(A9,Overrides!$A:$A,0)),"") | P9: =IFERROR(INDEX(Overrides!$B:$B,MATCH(A9,Overrides!$A:$A,0)),"") | Q9: =IFERROR(INDEX(Overrides!$F:$F,MATCH(A9,Overrides!$A:$A,0)),"") | R9: =ISNUMBER(MATCH(A9,Overrides!$A:$A,0)) | S9: =OR(ROUND(L9-ROUND(G9-T9,2),2)<=0,AND(I9,K9<>"",(A9-D9+1)=K9)) | T9: =IF(M9<>"",M9,ROUND(L9*F9,2)) | U9: =IF(R9,IF(O9<>"",O9,IF(N9<>"",ROUND(L9-N9,2),ROUND((IF(P9<>"",P9,G9))-T9,2))),IF(H9,0,IF(S9,L9,ROUND(G9-T9,2)))) | V9: =IF(R9,IF(P9<>"",P9,ROUND(T9+U9,2)),IF(H9,T9,IF(S9,ROUND(T9+U9,2),G9))) | W9: =IF(R9,IF(N9<>"",N9,ROUND(L9-U9,2)),IF(H9,L9,IF(S9,0,ROUND(L9-U9,2)))) | X9: =IFERROR(MIN(INDEX(LumpSums!$B:$B,MATCH(A9,LumpSums!$A:$A,0)),W9),0) | Y9: =ROUND(U9+X9,2) | Z9: =ROUND(V9+X9,2) | AA9: =ROUND(W9-X9,2) | AB9: =AND(AB8,L9>0) | AC9: =IF(PMI_Costs!$B$8=0,0,ROUND(PMI_Costs!$B$8*(1+PMI_Costs!$B$9/100)^INT((A9-1)/12)/12,2)) | AD9: =IF(PMI_Costs!$B$10=0,0,ROUND(PMI_Costs!$B$10*(1+PMI_Costs!$B$11/100)^INT((A9-1)/12)/12,2)) | AE9: =IF(PMI_Costs!$B$12=0,0,ROUND(PMI_Costs!$B$12*(1+PMI_Costs!$B$13/100)^INT((A9-1)/12)/12,2)) | AF9: =IF(PMI_Costs!$B$5=0,0,AA9/PMI_Costs!$B$5) | AG9: =AND(PMI_Costs!$B$4>0,AF9>PMI_Costs!$B$6/100) | AH9: =IF(AG9,ROUND(Segments!$G$5*PMI_Costs!$B$4/100/12,2),0) | AI9: =AND(NOT(AG9),AG8)
A10: 6 | B10: =SUMPRODUCT((Segments!$J$5:$J$12<>"")*(Segments!$J$5:$J$12<=A10)) | C10: =INDEX(Segments!$B$5:$B$12,B10) | D10: =INDEX(Segments!$J$5:$J$12,B10) | E10: =DATE(YEAR(C10)+INT((MONTH(C10)-1+(A10-D10))/12),MOD(MONTH(C10)-1+(A10-D10),12)+1,1)+(DAY(C10)-1) | F10: =INDEX(Segments!$C$5:$C$12,B10)/100/12 | G10: =INDEX(Segments!$L$5:$L$12,B10) | H10: =INDEX(Segments!$I$5:$I$12,B10)="Y" | I10: =INDEX(Segments!$F$5:$F$12,B10)="" | J10: =INDEX(Segments!$K$5:$K$12,B10) | K10: =IF(INDEX(Segments!$F$5:$F$12,B10)<>"",INDEX(Segments!$F$5:$F$12,B10),IF(INDEX(Segments!$E$5:$E$12,B10)<>"",INDEX(Segments!$E$5:$E$12,B10),"")) | L10: =AA9 | M10: =IFERROR(INDEX(Overrides!$C:$C,MATCH(A10,Overrides!$A:$A,0)),"") | N10: =IFERROR(INDEX(Overrides!$E:$E,MATCH(A10,Overrides!$A:$A,0)),"") | O10: =IFERROR(INDEX(Overrides!$D:$D,MATCH(A10,Overrides!$A:$A,0)),"") | P10: =IFERROR(INDEX(Overrides!$B:$B,MATCH(A10,Overrides!$A:$A,0)),"") | Q10: =IFERROR(INDEX(Overrides!$F:$F,MATCH(A10,Overrides!$A:$A,0)),"") | R10: =ISNUMBER(MATCH(A10,Overrides!$A:$A,0)) | S10: =OR(ROUND(L10-ROUND(G10-T10,2),2)<=0,AND(I10,K10<>"",(A10-D10+1)=K10)) | T10: =IF(M10<>"",M10,ROUND(L10*F10,2)) | U10: =IF(R10,IF(O10<>"",O10,IF(N10<>"",ROUND(L10-N10,2),ROUND((IF(P10<>"",P10,G10))-T10,2))),IF(H10,0,IF(S10,L10,ROUND(G10-T10,2)))) | V10: =IF(R10,IF(P10<>"",P10,ROUND(T10+U10,2)),IF(H10,T10,IF(S10,ROUND(T10+U10,2),G10))) | W10: =IF(R10,IF(N10<>"",N10,ROUND(L10-U10,2)),IF(H10,L10,IF(S10,0,ROUND(L10-U10,2)))) | X10: =IFERROR(MIN(INDEX(LumpSums!$B:$B,MATCH(A10,LumpSums!$A:$A,0)),W10),0) | Y10: =ROUND(U10+X10,2) | Z10: =ROUND(V10+X10,2) | AA10: =ROUND(W10-X10,2) | AB10: =AND(AB9,L10>0) | AC10: =IF(PMI_Costs!$B$8=0,0,ROUND(PMI_Costs!$B$8*(1+PMI_Costs!$B$9/100)^INT((A10-1)/12)/12,2)) | AD10: =IF(PMI_Costs!$B$10=0,0,ROUND(PMI_Costs!$B$10*(1+PMI_Costs!$B$11/100)^INT((A10-1)/12)/12,2)) | AE10: =IF(PMI_Costs!$B$12=0,0,ROUND(PMI_Costs!$B$12*(1+PMI_Costs!$B$13/100)^INT((A10-1)/12)/12,2)) | AF10: =IF(PMI_Costs!$B$5=0,0,AA10/PMI_Costs!$B$5) | AG10: =AND(PMI_Costs!$B$4>0,AF10>PMI_Costs!$B$6/100) | AH10: =IF(AG10,ROUND(Segments!$G$5*PMI_Costs!$B$4/100/12,2),0) | AI10: =AND(NOT(AG10),AG9)
A11: 7 | B11: =SUMPRODUCT((Segments!$J$5:$J$12<>"")*(Segments!$J$5:$J$12<=A11)) | C11: =INDEX(Segments!$B$5:$B$12,B11) | D11: =INDEX(Segments!$J$5:$J$12,B11) | E11: =DATE(YEAR(C11)+INT((MONTH(C11)-1+(A11-D11))/12),MOD(MONTH(C11)-1+(A11-D11),12)+1,1)+(DAY(C11)-1) | F11: =INDEX(Segments!$C$5:$C$12,B11)/100/12 | G11: =INDEX(Segments!$L$5:$L$12,B11) | H11: =INDEX(Segments!$I$5:$I$12,B11)="Y" | I11: =INDEX(Segments!$F$5:$F$12,B11)="" | J11: =INDEX(Segments!$K$5:$K$12,B11) | K11: =IF(INDEX(Segments!$F$5:$F$12,B11)<>"",INDEX(Segments!$F$5:$F$12,B11),IF(INDEX(Segments!$E$5:$E$12,B11)<>"",INDEX(Segments!$E$5:$E$12,B11),"")) | L11: =AA10 | M11: =IFERROR(INDEX(Overrides!$C:$C,MATCH(A11,Overrides!$A:$A,0)),"") | N11: =IFERROR(INDEX(Overrides!$E:$E,MATCH(A11,Overrides!$A:$A,0)),"") | O11: =IFERROR(INDEX(Overrides!$D:$D,MATCH(A11,Overrides!$A:$A,0)),"") | P11: =IFERROR(INDEX(Overrides!$B:$B,MATCH(A11,Overrides!$A:$A,0)),"") | Q11: =IFERROR(INDEX(Overrides!$F:$F,MATCH(A11,Overrides!$A:$A,0)),"") | R11: =ISNUMBER(MATCH(A11,Overrides!$A:$A,0)) | S11: =OR(ROUND(L11-ROUND(G11-T11,2),2)<=0,AND(I11,K11<>"",(A11-D11+1)=K11)) | T11: =IF(M11<>"",M11,ROUND(L11*F11,2)) | U11: =IF(R11,IF(O11<>"",O11,IF(N11<>"",ROUND(L11-N11,2),ROUND((IF(P11<>"",P11,G11))-T11,2))),IF(H11,0,IF(S11,L11,ROUND(G11-T11,2)))) | V11: =IF(R11,IF(P11<>"",P11,ROUND(T11+U11,2)),IF(H11,T11,IF(S11,ROUND(T11+U11,2),G11))) | W11: =IF(R11,IF(N11<>"",N11,ROUND(L11-U11,2)),IF(H11,L11,IF(S11,0,ROUND(L11-U11,2)))) | X11: =IFERROR(MIN(INDEX(LumpSums!$B:$B,MATCH(A11,LumpSums!$A:$A,0)),W11),0) | Y11: =ROUND(U11+X11,2) | Z11: =ROUND(V11+X11,2) | AA11: =ROUND(W11-X11,2) | AB11: =AND(AB10,L11>0) | AC11: =IF(PMI_Costs!$B$8=0,0,ROUND(PMI_Costs!$B$8*(1+PMI_Costs!$B$9/100)^INT((A11-1)/12)/12,2)) | AD11: =IF(PMI_Costs!$B$10=0,0,ROUND(PMI_Costs!$B$10*(1+PMI_Costs!$B$11/100)^INT((A11-1)/12)/12,2)) | AE11: =IF(PMI_Costs!$B$12=0,0,ROUND(PMI_Costs!$B$12*(1+PMI_Costs!$B$13/100)^INT((A11-1)/12)/12,2)) | AF11: =IF(PMI_Costs!$B$5=0,0,AA11/PMI_Costs!$B$5) | AG11: =AND(PMI_Costs!$B$4>0,AF11>PMI_Costs!$B$6/100) | AH11: =IF(AG11,ROUND(Segments!$G$5*PMI_Costs!$B$4/100/12,2),0) | AI11: =AND(NOT(AG11),AG10)
A12: 8 | B12: =SUMPRODUCT((Segments!$J$5:$J$12<>"")*(Segments!$J$5:$J$12<=A12)) | C12: =INDEX(Segments!$B$5:$B$12,B12) | D12: =INDEX(Segments!$J$5:$J$12,B12) | E12: =DATE(YEAR(C12)+INT((MONTH(C12)-1+(A12-D12))/12),MOD(MONTH(C12)-1+(A12-D12),12)+1,1)+(DAY(C12)-1) | F12: =INDEX(Segments!$C$5:$C$12,B12)/100/12 | G12: =INDEX(Segments!$L$5:$L$12,B12) | H12: =INDEX(Segments!$I$5:$I$12,B12)="Y" | I12: =INDEX(Segments!$F$5:$F$12,B12)="" | J12: =INDEX(Segments!$K$5:$K$12,B12) | K12: =IF(INDEX(Segments!$F$5:$F$12,B12)<>"",INDEX(Segments!$F$5:$F$12,B12),IF(INDEX(Segments!$E$5:$E$12,B12)<>"",INDEX(Segments!$E$5:$E$12,B12),"")) | L12: =AA11 | M12: =IFERROR(INDEX(Overrides!$C:$C,MATCH(A12,Overrides!$A:$A,0)),"") | N12: =IFERROR(INDEX(Overrides!$E:$E,MATCH(A12,Overrides!$A:$A,0)),"") | O12: =IFERROR(INDEX(Overrides!$D:$D,MATCH(A12,Overrides!$A:$A,0)),"") | P12: =IFERROR(INDEX(Overrides!$B:$B,MATCH(A12,Overrides!$A:$A,0)),"") | Q12: =IFERROR(INDEX(Overrides!$F:$F,MATCH(A12,Overrides!$A:$A,0)),"") | R12: =ISNUMBER(MATCH(A12,Overrides!$A:$A,0)) | S12: =OR(ROUND(L12-ROUND(G12-T12,2),2)<=0,AND(I12,K12<>"",(A12-D12+1)=K12)) | T12: =IF(M12<>"",M12,ROUND(L12*F12,2)) | U12: =IF(R12,IF(O12<>"",O12,IF(N12<>"",ROUND(L12-N12,2),ROUND((IF(P12<>"",P12,G12))-T12,2))),IF(H12,0,IF(S12,L12,ROUND(G12-T12,2)))) | V12: =IF(R12,IF(P12<>"",P12,ROUND(T12+U12,2)),IF(H12,T12,IF(S12,ROUND(T12+U12,2),G12))) | W12: =IF(R12,IF(N12<>"",N12,ROUND(L12-U12,2)),IF(H12,L12,IF(S12,0,ROUND(L12-U12,2)))) | X12: =IFERROR(MIN(INDEX(LumpSums!$B:$B,MATCH(A12,LumpSums!$A:$A,0)),W12),0) | Y12: =ROUND(U12+X12,2) | Z12: =ROUND(V12+X12,2) | AA12: =ROUND(W12-X12,2) | AB12: =AND(AB11,L12>0) | AC12: =IF(PMI_Costs!$B$8=0,0,ROUND(PMI_Costs!$B$8*(1+PMI_Costs!$B$9/100)^INT((A12-1)/12)/12,2)) | AD12: =IF(PMI_Costs!$B$10=0,0,ROUND(PMI_Costs!$B$10*(1+PMI_Costs!$B$11/100)^INT((A12-1)/12)/12,2)) | AE12: =IF(PMI_Costs!$B$12=0,0,ROUND(PMI_Costs!$B$12*(1+PMI_Costs!$B$13/100)^INT((A12-1)/12)/12,2)) | AF12: =IF(PMI_Costs!$B$5=0,0,AA12/PMI_Costs!$B$5) | AG12: =AND(PMI_Costs!$B$4>0,AF12>PMI_Costs!$B$6/100) | AH12: =IF(AG12,ROUND(Segments!$G$5*PMI_Costs!$B$4/100/12,2),0) | AI12: =AND(NOT(AG12),AG11)
A13: 9 | B13: =SUMPRODUCT((Segments!$J$5:$J$12<>"")*(Segments!$J$5:$J$12<=A13)) | C13: =INDEX(Segments!$B$5:$B$12,B13) | D13: =INDEX(Segments!$J$5:$J$12,B13) | E13: =DATE(YEAR(C13)+INT((MONTH(C13)-1+(A13-D13))/12),MOD(MONTH(C13)-1+(A13-D13),12)+1,1)+(DAY(C13)-1) | F13: =INDEX(Segments!$C$5:$C$12,B13)/100/12 | G13: =INDEX(Segments!$L$5:$L$12,B13) | H13: =INDEX(Segments!$I$5:$I$12,B13)="Y" | I13: =INDEX(Segments!$F$5:$F$12,B13)="" | J13: =INDEX(Segments!$K$5:$K$12,B13) | K13: =IF(INDEX(Segments!$F$5:$F$12,B13)<>"",INDEX(Segments!$F$5:$F$12,B13),IF(INDEX(Segments!$E$5:$E$12,B13)<>"",INDEX(Segments!$E$5:$E$12,B13),"")) | L13: =AA12 | M13: =IFERROR(INDEX(Overrides!$C:$C,MATCH(A13,Overrides!$A:$A,0)),"") | N13: =IFERROR(INDEX(Overrides!$E:$E,MATCH(A13,Overrides!$A:$A,0)),"") | O13: =IFERROR(INDEX(Overrides!$D:$D,MATCH(A13,Overrides!$A:$A,0)),"") | P13: =IFERROR(INDEX(Overrides!$B:$B,MATCH(A13,Overrides!$A:$A,0)),"") | Q13: =IFERROR(INDEX(Overrides!$F:$F,MATCH(A13,Overrides!$A:$A,0)),"") | R13: =ISNUMBER(MATCH(A13,Overrides!$A:$A,0)) | S13: =OR(ROUND(L13-ROUND(G13-T13,2),2)<=0,AND(I13,K13<>"",(A13-D13+1)=K13)) | T13: =IF(M13<>"",M13,ROUND(L13*F13,2)) | U13: =IF(R13,IF(O13<>"",O13,IF(N13<>"",ROUND(L13-N13,2),ROUND((IF(P13<>"",P13,G13))-T13,2))),IF(H13,0,IF(S13,L13,ROUND(G13-T13,2)))) | V13: =IF(R13,IF(P13<>"",P13,ROUND(T13+U13,2)),IF(H13,T13,IF(S13,ROUND(T13+U13,2),G13))) | W13: =IF(R13,IF(N13<>"",N13,ROUND(L13-U13,2)),IF(H13,L13,IF(S13,0,ROUND(L13-U13,2)))) | X13: =IFERROR(MIN(INDEX(LumpSums!$B:$B,MATCH(A13,LumpSums!$A:$A,0)),W13),0) | Y13: =ROUND(U13+X13,2) | Z13: =ROUND(V13+X13,2) | AA13: =ROUND(W13-X13,2) | AB13: =AND(AB12,L13>0) | AC13: =IF(PMI_Costs!$B$8=0,0,ROUND(PMI_Costs!$B$8*(1+PMI_Costs!$B$9/100)^INT((A13-1)/12)/12,2)) | AD13: =IF(PMI_Costs!$B$10=0,0,ROUND(PMI_Costs!$B$10*(1+PMI_Costs!$B$11/100)^INT((A13-1)/12)/12,2)) | AE13: =IF(PMI_Costs!$B$12=0,0,ROUND(PMI_Costs!$B$12*(1+PMI_Costs!$B$13/100)^INT((A13-1)/12)/12,2)) | AF13: =IF(PMI_Costs!$B$5=0,0,AA13/PMI_Costs!$B$5) | AG13: =AND(PMI_Costs!$B$4>0,AF13>PMI_Costs!$B$6/100) | AH13: =IF(AG13,ROUND(Segments!$G$5*PMI_Costs!$B$4/100/12,2),0) | AI13: =AND(NOT(AG13),AG12)
A14: 10 | B14: =SUMPRODUCT((Segments!$J$5:$J$12<>"")*(Segments!$J$5:$J$12<=A14)) | C14: =INDEX(Segments!$B$5:$B$12,B14) | D14: =INDEX(Segments!$J$5:$J$12,B14) | E14: =DATE(YEAR(C14)+INT((MONTH(C14)-1+(A14-D14))/12),MOD(MONTH(C14)-1+(A14-D14),12)+1,1)+(DAY(C14)-1) | F14: =INDEX(Segments!$C$5:$C$12,B14)/100/12 | G14: =INDEX(Segments!$L$5:$L$12,B14) | H14: =INDEX(Segments!$I$5:$I$12,B14)="Y" | I14: =INDEX(Segments!$F$5:$F$12,B14)="" | J14: =INDEX(Segments!$K$5:$K$12,B14) | K14: =IF(INDEX(Segments!$F$5:$F$12,B14)<>"",INDEX(Segments!$F$5:$F$12,B14),IF(INDEX(Segments!$E$5:$E$12,B14)<>"",INDEX(Segments!$E$5:$E$12,B14),"")) | L14: =AA13 | M14: =IFERROR(INDEX(Overrides!$C:$C,MATCH(A14,Overrides!$A:$A,0)),"") | N14: =IFERROR(INDEX(Overrides!$E:$E,MATCH(A14,Overrides!$A:$A,0)),"") | O14: =IFERROR(INDEX(Overrides!$D:$D,MATCH(A14,Overrides!$A:$A,0)),"") | P14: =IFERROR(INDEX(Overrides!$B:$B,MATCH(A14,Overrides!$A:$A,0)),"") | Q14: =IFERROR(INDEX(Overrides!$F:$F,MATCH(A14,Overrides!$A:$A,0)),"") | R14: =ISNUMBER(MATCH(A14,Overrides!$A:$A,0)) | S14: =OR(ROUND(L14-ROUND(G14-T14,2),2)<=0,AND(I14,K14<>"",(A14-D14+1)=K14)) | T14: =IF(M14<>"",M14,ROUND(L14*F14,2)) | U14: =IF(R14,IF(O14<>"",O14,IF(N14<>"",ROUND(L14-N14,2),ROUND((IF(P14<>"",P14,G14))-T14,2))),IF(H14,0,IF(S14,L14,ROUND(G14-T14,2)))) | V14: =IF(R14,IF(P14<>"",P14,ROUND(T14+U14,2)),IF(H14,T14,IF(S14,ROUND(T14+U14,2),G14))) | W14: =IF(R14,IF(N14<>"",N14,ROUND(L14-U14,2)),IF(H14,L14,IF(S14,0,ROUND(L14-U14,2)))) | X14: =IFERROR(MIN(INDEX(LumpSums!$B:$B,MATCH(A14,LumpSums!$A:$A,0)),W14),0) | Y14: =ROUND(U14+X14,2) | Z14: =ROUND(V14+X14,2) | AA14: =ROUND(W14-X14,2) | AB14: =AND(AB13,L14>0) | AC14: =IF(PMI_Costs!$B$8=0,0,ROUND(PMI_Costs!$B$8*(1+PMI_Costs!$B$9/100)^INT((A14-1)/12)/12,2)) | AD14: =IF(PMI_Costs!$B$10=0,0,ROUND(PMI_Costs!$B$10*(1+PMI_Costs!$B$11/100)^INT((A14-1)/12)/12,2)) | AE14: =IF(PMI_Costs!$B$12=0,0,ROUND(PMI_Costs!$B$12*(1+PMI_Costs!$B$13/100)^INT((A14-1)/12)/12,2)) | AF14: =IF(PMI_Costs!$B$5=0,0,AA14/PMI_Costs!$B$5) | AG14: =AND(PMI_Costs!$B$4>0,AF14>PMI_Costs!$B$6/100) | AH14: =IF(AG14,ROUND(Segments!$G$5*PMI_Costs!$B$4/100/12,2),0) | AI14: =AND(NOT(AG14),AG13)
A15: 11 | B15: =SUMPRODUCT((Segments!$J$5:$J$12<>"")*(Segments!$J$5:$J$12<=A15)) | C15: =INDEX(Segments!$B$5:$B$12,B15) | D15: =INDEX(Segments!$J$5:$J$12,B15) | E15: =DATE(YEAR(C15)+INT((MONTH(C15)-1+(A15-D15))/12),MOD(MONTH(C15)-1+(A15-D15),12)+1,1)+(DAY(C15)-1) | F15: =INDEX(Segments!$C$5:$C$12,B15)/100/12 | G15: =INDEX(Segments!$L$5:$L$12,B15) | H15: =INDEX(Segments!$I$5:$I$12,B15)="Y" | I15: =INDEX(Segments!$F$5:$F$12,B15)="" | J15: =INDEX(Segments!$K$5:$K$12,B15) | K15: =IF(INDEX(Segments!$F$5:$F$12,B15)<>"",INDEX(Segments!$F$5:$F$12,B15),IF(INDEX(Segments!$E$5:$E$12,B15)<>"",INDEX(Segments!$E$5:$E$12,B15),"")) | L15: =AA14 | M15: =IFERROR(INDEX(Overrides!$C:$C,MATCH(A15,Overrides!$A:$A,0)),"") | N15: =IFERROR(INDEX(Overrides!$E:$E,MATCH(A15,Overrides!$A:$A,0)),"") | O15: =IFERROR(INDEX(Overrides!$D:$D,MATCH(A15,Overrides!$A:$A,0)),"") | P15: =IFERROR(INDEX(Overrides!$B:$B,MATCH(A15,Overrides!$A:$A,0)),"") | Q15: =IFERROR(INDEX(Overrides!$F:$F,MATCH(A15,Overrides!$A:$A,0)),"") | R15: =ISNUMBER(MATCH(A15,Overrides!$A:$A,0)) | S15: =OR(ROUND(L15-ROUND(G15-T15,2),2)<=0,AND(I15,K15<>"",(A15-D15+1)=K15)) | T15: =IF(M15<>"",M15,ROUND(L15*F15,2)) | U15: =IF(R15,IF(O15<>"",O15,IF(N15<>"",ROUND(L15-N15,2),ROUND((IF(P15<>"",P15,G15))-T15,2))),IF(H15,0,IF(S15,L15,ROUND(G15-T15,2)))) | V15: =IF(R15,IF(P15<>"",P15,ROUND(T15+U15,2)),IF(H15,T15,IF(S15,ROUND(T15+U15,2),G15))) | W15: =IF(R15,IF(N15<>"",N15,ROUND(L15-U15,2)),IF(H15,L15,IF(S15,0,ROUND(L15-U15,2)))) | X15: =IFERROR(MIN(INDEX(LumpSums!$B:$B,MATCH(A15,LumpSums!$A:$A,0)),W15),0) | Y15: =ROUND(U15+X15,2) | Z15: =ROUND(V15+X15,2) | AA15: =ROUND(W15-X15,2) | AB15: =AND(AB14,L15>0) | AC15: =IF(PMI_Costs!$B$8=0,0,ROUND(PMI_Costs!$B$8*(1+PMI_Costs!$B$9/100)^INT((A15-1)/12)/12,2)) | AD15: =IF(PMI_Costs!$B$10=0,0,ROUND(PMI_Costs!$B$10*(1+PMI_Costs!$B$11/100)^INT((A15-1)/12)/12,2)) | AE15: =IF(PMI_Costs!$B$12=0,0,ROUND(PMI_Costs!$B$12*(1+PMI_Costs!$B$13/100)^INT((A15-1)/12)/12,2)) | AF15: =IF(PMI_Costs!$B$5=0,0,AA15/PMI_Costs!$B$5) | AG15: =AND(PMI_Costs!$B$4>0,AF15>PMI_Costs!$B$6/100) | AH15: =IF(AG15,ROUND(Segments!$G$5*PMI_Costs!$B$4/100/12,2),0) | AI15: =AND(NOT(AG15),AG14)
A16: 12 | B16: =SUMPRODUCT((Segments!$J$5:$J$12<>"")*(Segments!$J$5:$J$12<=A16)) | C16: =INDEX(Segments!$B$5:$B$12,B16) | D16: =INDEX(Segments!$J$5:$J$12,B16) | E16: =DATE(YEAR(C16)+INT((MONTH(C16)-1+(A16-D16))/12),MOD(MONTH(C16)-1+(A16-D16),12)+1,1)+(DAY(C16)-1) | F16: =INDEX(Segments!$C$5:$C$12,B16)/100/12 | G16: =INDEX(Segments!$L$5:$L$12,B16) | H16: =INDEX(Segments!$I$5:$I$12,B16)="Y" | I16: =INDEX(Segments!$F$5:$F$12,B16)="" | J16: =INDEX(Segments!$K$5:$K$12,B16) | K16: =IF(INDEX(Segments!$F$5:$F$12,B16)<>"",INDEX(Segments!$F$5:$F$12,B16),IF(INDEX(Segments!$E$5:$E$12,B16)<>"",INDEX(Segments!$E$5:$E$12,B16),"")) | L16: =AA15 | M16: =IFERROR(INDEX(Overrides!$C:$C,MATCH(A16,Overrides!$A:$A,0)),"") | N16: =IFERROR(INDEX(Overrides!$E:$E,MATCH(A16,Overrides!$A:$A,0)),"") | O16: =IFERROR(INDEX(Overrides!$D:$D,MATCH(A16,Overrides!$A:$A,0)),"") | P16: =IFERROR(INDEX(Overrides!$B:$B,MATCH(A16,Overrides!$A:$A,0)),"") | Q16: =IFERROR(INDEX(Overrides!$F:$F,MATCH(A16,Overrides!$A:$A,0)),"") | R16: =ISNUMBER(MATCH(A16,Overrides!$A:$A,0)) | S16: =OR(ROUND(L16-ROUND(G16-T16,2),2)<=0,AND(I16,K16<>"",(A16-D16+1)=K16)) | T16: =IF(M16<>"",M16,ROUND(L16*F16,2)) | U16: =IF(R16,IF(O16<>"",O16,IF(N16<>"",ROUND(L16-N16,2),ROUND((IF(P16<>"",P16,G16))-T16,2))),IF(H16,0,IF(S16,L16,ROUND(G16-T16,2)))) | V16: =IF(R16,IF(P16<>"",P16,ROUND(T16+U16,2)),IF(H16,T16,IF(S16,ROUND(T16+U16,2),G16))) | W16: =IF(R16,IF(N16<>"",N16,ROUND(L16-U16,2)),IF(H16,L16,IF(S16,0,ROUND(L16-U16,2)))) | X16: =IFERROR(MIN(INDEX(LumpSums!$B:$B,MATCH(A16,LumpSums!$A:$A,0)),W16),0) | Y16: =ROUND(U16+X16,2) | Z16: =ROUND(V16+X16,2) | AA16: =ROUND(W16-X16,2) | AB16: =AND(AB15,L16>0) | AC16: =IF(PMI_Costs!$B$8=0,0,ROUND(PMI_Costs!$B$8*(1+PMI_Costs!$B$9/100)^INT((A16-1)/12)/12,2)) | AD16: =IF(PMI_Costs!$B$10=0,0,ROUND(PMI_Costs!$B$10*(1+PMI_Costs!$B$11/100)^INT((A16-1)/12)/12,2)) | AE16: =IF(PMI_Costs!$B$12=0,0,ROUND(PMI_Costs!$B$12*(1+PMI_Costs!$B$13/100)^INT((A16-1)/12)/12,2)) | AF16: =IF(PMI_Costs!$B$5=0,0,AA16/PMI_Costs!$B$5) | AG16: =AND(PMI_Costs!$B$4>0,AF16>PMI_Costs!$B$6/100) | AH16: =IF(AG16,ROUND(Segments!$G$5*PMI_Costs!$B$4/100/12,2),0) | AI16: =AND(NOT(AG16),AG15)
A17: 13 | B17: =SUMPRODUCT((Segments!$J$5:$J$12<>"")*(Segments!$J$5:$J$12<=A17)) | C17: =INDEX(Segments!$B$5:$B$12,B17) | D17: =INDEX(Segments!$J$5:$J$12,B17) | E17: =DATE(YEAR(C17)+INT((MONTH(C17)-1+(A17-D17))/12),MOD(MONTH(C17)-1+(A17-D17),12)+1,1)+(DAY(C17)-1) | F17: =INDEX(Segments!$C$5:$C$12,B17)/100/12 | G17: =INDEX(Segments!$L$5:$L$12,B17) | H17: =INDEX(Segments!$I$5:$I$12,B17)="Y" | I17: =INDEX(Segments!$F$5:$F$12,B17)="" | J17: =INDEX(Segments!$K$5:$K$12,B17) | K17: =IF(INDEX(Segments!$F$5:$F$12,B17)<>"",INDEX(Segments!$F$5:$F$12,B17),IF(INDEX(Segments!$E$5:$E$12,B17)<>"",INDEX(Segments!$E$5:$E$12,B17),"")) | L17: =AA16 | M17: =IFERROR(INDEX(Overrides!$C:$C,MATCH(A17,Overrides!$A:$A,0)),"") | N17: =IFERROR(INDEX(Overrides!$E:$E,MATCH(A17,Overrides!$A:$A,0)),"") | O17: =IFERROR(INDEX(Overrides!$D:$D,MATCH(A17,Overrides!$A:$A,0)),"") | P17: =IFERROR(INDEX(Overrides!$B:$B,MATCH(A17,Overrides!$A:$A,0)),"") | Q17: =IFERROR(INDEX(Overrides!$F:$F,MATCH(A17,Overrides!$A:$A,0)),"") | R17: =ISNUMBER(MATCH(A17,Overrides!$A:$A,0)) | S17: =OR(ROUND(L17-ROUND(G17-T17,2),2)<=0,AND(I17,K17<>"",(A17-D17+1)=K17)) | T17: =IF(M17<>"",M17,ROUND(L17*F17,2)) | U17: =IF(R17,IF(O17<>"",O17,IF(N17<>"",ROUND(L17-N17,2),ROUND((IF(P17<>"",P17,G17))-T17,2))),IF(H17,0,IF(S17,L17,ROUND(G17-T17,2)))) | V17: =IF(R17,IF(P17<>"",P17,ROUND(T17+U17,2)),IF(H17,T17,IF(S17,ROUND(T17+U17,2),G17))) | W17: =IF(R17,IF(N17<>"",N17,ROUND(L17-U17,2)),IF(H17,L17,IF(S17,0,ROUND(L17-U17,2)))) | X17: =IFERROR(MIN(INDEX(LumpSums!$B:$B,MATCH(A17,LumpSums!$A:$A,0)),W17),0) | Y17: =ROUND(U17+X17,2) | Z17: =ROUND(V17+X17,2) | AA17: =ROUND(W17-X17,2) | AB17: =AND(AB16,L17>0) | AC17: =IF(PMI_Costs!$B$8=0,0,ROUND(PMI_Costs!$B$8*(1+PMI_Costs!$B$9/100)^INT((A17-1)/12)/12,2)) | AD17: =IF(PMI_Costs!$B$10=0,0,ROUND(PMI_Costs!$B$10*(1+PMI_Costs!$B$11/100)^INT((A17-1)/12)/12,2)) | AE17: =IF(PMI_Costs!$B$12=0,0,ROUND(PMI_Costs!$B$12*(1+PMI_Costs!$B$13/100)^INT((A17-1)/12)/12,2)) | AF17: =IF(PMI_Costs!$B$5=0,0,AA17/PMI_Costs!$B$5) | AG17: =AND(PMI_Costs!$B$4>0,AF17>PMI_Costs!$B$6/100) | AH17: =IF(AG17,ROUND(Segments!$G$5*PMI_Costs!$B$4/100/12,2),0) | AI17: =AND(NOT(AG17),AG16)
... A364: 360 | B364: =SUMPRODUCT((Segments!$J$5:$J$12<>"")*(Segments!$J$5:$J$12<=A364)) | C364: =INDEX(Segments!$B$5:$B$12,B364) | D364: =INDEX(Segments!$J$5:$J$12,B364) | E364: =DATE(YEAR(C364)+INT((MONTH(C364)-1+(A364-D364))/12),MOD(MONTH(C364)-1+(A364-D364),12)+1,1)+(DAY(C364)-1) | F364: =INDEX(Segments!$C$5:$C$12,B364)/100/12 | G364: =INDEX(Segments!$L$5:$L$12,B364) | H364: =INDEX(Segments!$I$5:$I$12,B364)="Y" | I364: =INDEX(Segments!$F$5:$F$12,B364)="" | J364: =INDEX(Segments!$K$5:$K$12,B364) | K364: =IF(INDEX(Segments!$F$5:$F$12,B364)<>"",INDEX(Segments!$F$5:$F$12,B364),IF(INDEX(Segments!$E$5:$E$12,B364)<>"",INDEX(Segments!$E$5:$E$12,B364),"")) | L364: =AA363 | M364: =IFERROR(INDEX(Overrides!$C:$C,MATCH(A364,Overrides!$A:$A,0)),"") | N364: =IFERROR(INDEX(Overrides!$E:$E,MATCH(A364,Overrides!$A:$A,0)),"") | O364: =IFERROR(INDEX(Overrides!$D:$D,MATCH(A364,Overrides!$A:$A,0)),"") | P364: =IFERROR(INDEX(Overrides!$B:$B,MATCH(A364,Overrides!$A:$A,0)),"") | Q364: =IFERROR(INDEX(Overrides!$F:$F,MATCH(A364,Overrides!$A:$A,0)),"") | R364: =ISNUMBER(MATCH(A364,Overrides!$A:$A,0)) | S364: =OR(ROUND(L364-ROUND(G364-T364,2),2)<=0,AND(I364,K364<>"",(A364-D364+1)=K364)) | T364: =IF(M364<>"",M364,ROUND(L364*F364,2)) | U364: =IF(R364,IF(O364<>"",O364,IF(N364<>"",ROUND(L364-N364,2),ROUND((IF(P364<>"",P364,G364))-T364,2))),IF(H364,0,IF(S364,L364,ROUND(G364-T364,2)))) | V364: =IF(R364,IF(P364<>"",P364,ROUND(T364+U364,2)),IF(H364,T364,IF(S364,ROUND(T364+U364,2),G364))) | W364: =IF(R364,IF(N364<>"",N364,ROUND(L364-U364,2)),IF(H364,L364,IF(S364,0,ROUND(L364-U364,2)))) | X364: =IFERROR(MIN(INDEX(LumpSums!$B:$B,MATCH(A364,LumpSums!$A:$A,0)),W364),0) | Y364: =ROUND(U364+X364,2) | Z364: =ROUND(V364+X364,2) | AA364: =ROUND(W364-X364,2) | AB364: =AND(AB363,L364>0) | AC364: =IF(PMI_Costs!$B$8=0,0,ROUND(PMI_Costs!$B$8*(1+PMI_Costs!$B$9/100)^INT((A364-1)/12)/12,2)) | AD364: =IF(PMI_Costs!$B$10=0,0,ROUND(PMI_Costs!$B$10*(1+PMI_Costs!$B$11/100)^INT((A364-1)/12)/12,2)) | AE364: =IF(PMI_Costs!$B$12=0,0,ROUND(PMI_Costs!$B$12*(1+PMI_Costs!$B$13/100)^INT((A364-1)/12)/12,2)) | AF364: =IF(PMI_Costs!$B$5=0,0,AA364/PMI_Costs!$B$5) | AG364: =AND(PMI_Costs!$B$4>0,AF364>PMI_Costs!$B$6/100) | AH364: =IF(AG364,ROUND(Segments!$G$5*PMI_Costs!$B$4/100/12,2),0) | AI364: =AND(NOT(AG364),AG363)

Sheet Summary
A1: Summary (computed)
A2: Totals over the Schedule sheet's active rows only.
A4: Number of payments | B4: =COUNTIF(Schedule!$AB$5:$AB$364,TRUE)
A5: Total interest paid | B5: =SUMIFS(Schedule!$T$5:$T$364,Schedule!$AB$5:$AB$364,TRUE)
A6: Total principal paid (P&I only) | B6: =SUMIFS(Schedule!$Y$5:$Y$364,Schedule!$AB$5:$AB$364,TRUE)
A7: Total of payments (P&I) | B7: =SUMIFS(Schedule!$Z$5:$Z$364,Schedule!$AB$5:$AB$364,TRUE)
A8: Payoff date | B8: =SUMPRODUCT(MAX((Schedule!$AB$5:$AB$364)*(Schedule!$E$5:$E$364)))
A10: Total tax paid | B10: =SUMIFS(Schedule!$AC$5:$AC$364,Schedule!$AB$5:$AB$364,TRUE)
A11: Total insurance paid | B11: =SUMIFS(Schedule!$AD$5:$AD$364,Schedule!$AB$5:$AB$364,TRUE)
A12: Total HOA paid | B12: =SUMIFS(Schedule!$AE$5:$AE$364,Schedule!$AB$5:$AB$364,TRUE)
A13: Total PMI paid | B13: =SUMIFS(Schedule!$AH$5:$AH$364,Schedule!$AB$5:$AB$364,TRUE)
A14: Total cost of ownership | B14: =B7+B10+B11+B12+B13
A15: PMI dropped at payment # | B15: =IFERROR(INDEX(Schedule!$A$5:$A$364,MATCH(TRUE,Schedule!$AI$5:$AI$364,0)),IF(SUMPRODUCT((Schedule!$AB$5:$AB$364)*(Schedule!$AG$5:$AG$364))>0,"active through payoff","never"))
A17: Balloon segment index (last active row's segment) | B17: =SUMPRODUCT(MAX((Schedule!$AB$5:$AB$364)*(Schedule!$B$5:$B$364)))
A18: Balloon payment due? | B18: =IF(INDEX(Segments!$H:$H,B17+4)="Y","Yes","No")
A19: Balloon amount (if due) | B19: =IF(INDEX(Segments!$H:$H,B17+4)="Y",SUMPRODUCT(MAX((Schedule!$AB$5:$AB$364)*(Schedule!$W$5:$W$364))),"n/a")
A20: Balloon due date (if due) | B20: =IF(INDEX(Segments!$H:$H,B17+4)="Y",SUMPRODUCT(MAX((Schedule!$AB$5:$AB$364)*(Schedule!$E$5:$E$364))),"n/a")

Sheet YearlySummary
A1: Yearly Summary / Report Window
A2: Set 'Show through year' below (blue cell) to see cumulative totals for just the first N years -- e.g. enter 5 to answer 'how much interest will I pay in the first 5 years?' without scrolling the full Schedule.
A4: Show through year: | B4: 5
A6: Year | B6: Payments in Year | C6: Starting Balance | D6: Ending Balance | E6: Interest Paid | F6: Principal Paid
A7: 1 | B7: =SUMPRODUCT(((INT((Schedule!$A$5:$A$364-1)/12)+1=1))*(Schedule!$AB$5:$AB$364)) | C7: =IFERROR(INDEX(Schedule!$L$5:$L$364,MATCH(1,((INT((Schedule!$A$5:$A$364-1)/12)+1=1))*(Schedule!$AB$5:$AB$364),0)),"") | D7: =IFERROR(INDEX(Schedule!$AA$5:$AA$364,MATCH(SUMPRODUCT(MAX(((INT((Schedule!$A$5:$A$364-1)/12)+1=1))*(Schedule!$AB$5:$AB$364)*(Schedule!$A$5:$A$364))),Schedule!$A$5:$A$364,0)),"") | E7: =SUMPRODUCT(((INT((Schedule!$A$5:$A$364-1)/12)+1=1))*(Schedule!$AB$5:$AB$364)*(Schedule!$T$5:$T$364)) | F7: =SUMPRODUCT(((INT((Schedule!$A$5:$A$364-1)/12)+1=1))*(Schedule!$AB$5:$AB$364)*(Schedule!$Y$5:$Y$364))
A8: 2 | B8: =SUMPRODUCT(((INT((Schedule!$A$5:$A$364-1)/12)+1=2))*(Schedule!$AB$5:$AB$364)) | C8: =IFERROR(INDEX(Schedule!$L$5:$L$364,MATCH(1,((INT((Schedule!$A$5:$A$364-1)/12)+1=2))*(Schedule!$AB$5:$AB$364),0)),"") | D8: =IFERROR(INDEX(Schedule!$AA$5:$AA$364,MATCH(SUMPRODUCT(MAX(((INT((Schedule!$A$5:$A$364-1)/12)+1=2))*(Schedule!$AB$5:$AB$364)*(Schedule!$A$5:$A$364))),Schedule!$A$5:$A$364,0)),"") | E8: =SUMPRODUCT(((INT((Schedule!$A$5:$A$364-1)/12)+1=2))*(Schedule!$AB$5:$AB$364)*(Schedule!$T$5:$T$364)) | F8: =SUMPRODUCT(((INT((Schedule!$A$5:$A$364-1)/12)+1=2))*(Schedule!$AB$5:$AB$364)*(Schedule!$Y$5:$Y$364))
A9: 3 | B9: =SUMPRODUCT(((INT((Schedule!$A$5:$A$364-1)/12)+1=3))*(Schedule!$AB$5:$AB$364)) | C9: =IFERROR(INDEX(Schedule!$L$5:$L$364,MATCH(1,((INT((Schedule!$A$5:$A$364-1)/12)+1=3))*(Schedule!$AB$5:$AB$364),0)),"") | D9: =IFERROR(INDEX(Schedule!$AA$5:$AA$364,MATCH(SUMPRODUCT(MAX(((INT((Schedule!$A$5:$A$364-1)/12)+1=3))*(Schedule!$AB$5:$AB$364)*(Schedule!$A$5:$A$364))),Schedule!$A$5:$A$364,0)),"") | E9: =SUMPRODUCT(((INT((Schedule!$A$5:$A$364-1)/12)+1=3))*(Schedule!$AB$5:$AB$364)*(Schedule!$T$5:$T$364)) | F9: =SUMPRODUCT(((INT((Schedule!$A$5:$A$364-1)/12)+1=3))*(Schedule!$AB$5:$AB$364)*(Schedule!$Y$5:$Y$364))
A10: 4 | B10: =SUMPRODUCT(((INT((Schedule!$A$5:$A$364-1)/12)+1=4))*(Schedule!$AB$5:$AB$364)) | C10: =IFERROR(INDEX(Schedule!$L$5:$L$364,MATCH(1,((INT((Schedule!$A$5:$A$364-1)/12)+1=4))*(Schedule!$AB$5:$AB$364),0)),"") | D10: =IFERROR(INDEX(Schedule!$AA$5:$AA$364,MATCH(SUMPRODUCT(MAX(((INT((Schedule!$A$5:$A$364-1)/12)+1=4))*(Schedule!$AB$5:$AB$364)*(Schedule!$A$5:$A$364))),Schedule!$A$5:$A$364,0)),"") | E10: =SUMPRODUCT(((INT((Schedule!$A$5:$A$364-1)/12)+1=4))*(Schedule!$AB$5:$AB$364)*(Schedule!$T$5:$T$364)) | F10: =SUMPRODUCT(((INT((Schedule!$A$5:$A$364-1)/12)+1=4))*(Schedule!$AB$5:$AB$364)*(Schedule!$Y$5:$Y$364))
A11: 5 | B11: =SUMPRODUCT(((INT((Schedule!$A$5:$A$364-1)/12)+1=5))*(Schedule!$AB$5:$AB$364)) | C11: =IFERROR(INDEX(Schedule!$L$5:$L$364,MATCH(1,((INT((Schedule!$A$5:$A$364-1)/12)+1=5))*(Schedule!$AB$5:$AB$364),0)),"") | D11: =IFERROR(INDEX(Schedule!$AA$5:$AA$364,MATCH(SUMPRODUCT(MAX(((INT((Schedule!$A$5:$A$364-1)/12)+1=5))*(Schedule!$AB$5:$AB$364)*(Schedule!$A$5:$A$364))),Schedule!$A$5:$A$364,0)),"") | E11: =SUMPRODUCT(((INT((Schedule!$A$5:$A$364-1)/12)+1=5))*(Schedule!$AB$5:$AB$364)*(Schedule!$T$5:$T$364)) | F11: =SUMPRODUCT(((INT((Schedule!$A$5:$A$364-1)/12)+1=5))*(Schedule!$AB$5:$AB$364)*(Schedule!$Y$5:$Y$364))
A12: 6 | B12: =SUMPRODUCT(((INT((Schedule!$A$5:$A$364-1)/12)+1=6))*(Schedule!$AB$5:$AB$364)) | C12: =IFERROR(INDEX(Schedule!$L$5:$L$364,MATCH(1,((INT((Schedule!$A$5:$A$364-1)/12)+1=6))*(Schedule!$AB$5:$AB$364),0)),"") | D12: =IFERROR(INDEX(Schedule!$AA$5:$AA$364,MATCH(SUMPRODUCT(MAX(((INT((Schedule!$A$5:$A$364-1)/12)+1=6))*(Schedule!$AB$5:$AB$364)*(Schedule!$A$5:$A$364))),Schedule!$A$5:$A$364,0)),"") | E12: =SUMPRODUCT(((INT((Schedule!$A$5:$A$364-1)/12)+1=6))*(Schedule!$AB$5:$AB$364)*(Schedule!$T$5:$T$364)) | F12: =SUMPRODUCT(((INT((Schedule!$A$5:$A$364-1)/12)+1=6))*(Schedule!$AB$5:$AB$364)*(Schedule!$Y$5:$Y$364))
A13: 7 | B13: =SUMPRODUCT(((INT((Schedule!$A$5:$A$364-1)/12)+1=7))*(Schedule!$AB$5:$AB$364)) | C13: =IFERROR(INDEX(Schedule!$L$5:$L$364,MATCH(1,((INT((Schedule!$A$5:$A$364-1)/12)+1=7))*(Schedule!$AB$5:$AB$364),0)),"") | D13: =IFERROR(INDEX(Schedule!$AA$5:$AA$364,MATCH(SUMPRODUCT(MAX(((INT((Schedule!$A$5:$A$364-1)/12)+1=7))*(Schedule!$AB$5:$AB$364)*(Schedule!$A$5:$A$364))),Schedule!$A$5:$A$364,0)),"") | E13: =SUMPRODUCT(((INT((Schedule!$A$5:$A$364-1)/12)+1=7))*(Schedule!$AB$5:$AB$364)*(Schedule!$T$5:$T$364)) | F13: =SUMPRODUCT(((INT((Schedule!$A$5:$A$364-1)/12)+1=7))*(Schedule!$AB$5:$AB$364)*(Schedule!$Y$5:$Y$364))
A14: 8 | B14: =SUMPRODUCT(((INT((Schedule!$A$5:$A$364-1)/12)+1=8))*(Schedule!$AB$5:$AB$364)) | C14: =IFERROR(INDEX(Schedule!$L$5:$L$364,MATCH(1,((INT((Schedule!$A$5:$A$364-1)/12)+1=8))*(Schedule!$AB$5:$AB$364),0)),"") | D14: =IFERROR(INDEX(Schedule!$AA$5:$AA$364,MATCH(SUMPRODUCT(MAX(((INT((Schedule!$A$5:$A$364-1)/12)+1=8))*(Schedule!$AB$5:$AB$364)*(Schedule!$A$5:$A$364))),Schedule!$A$5:$A$364,0)),"") | E14: =SUMPRODUCT(((INT((Schedule!$A$5:$A$364-1)/12)+1=8))*(Schedule!$AB$5:$AB$364)*(Schedule!$T$5:$T$364)) | F14: =SUMPRODUCT(((INT((Schedule!$A$5:$A$364-1)/12)+1=8))*(Schedule!$AB$5:$AB$364)*(Schedule!$Y$5:$Y$364))
A15: 9 | B15: =SUMPRODUCT(((INT((Schedule!$A$5:$A$364-1)/12)+1=9))*(Schedule!$AB$5:$AB$364)) | C15: =IFERROR(INDEX(Schedule!$L$5:$L$364,MATCH(1,((INT((Schedule!$A$5:$A$364-1)/12)+1=9))*(Schedule!$AB$5:$AB$364),0)),"") | D15: =IFERROR(INDEX(Schedule!$AA$5:$AA$364,MATCH(SUMPRODUCT(MAX(((INT((Schedule!$A$5:$A$364-1)/12)+1=9))*(Schedule!$AB$5:$AB$364)*(Schedule!$A$5:$A$364))),Schedule!$A$5:$A$364,0)),"") | E15: =SUMPRODUCT(((INT((Schedule!$A$5:$A$364-1)/12)+1=9))*(Schedule!$AB$5:$AB$364)*(Schedule!$T$5:$T$364)) | F15: =SUMPRODUCT(((INT((Schedule!$A$5:$A$364-1)/12)+1=9))*(Schedule!$AB$5:$AB$364)*(Schedule!$Y$5:$Y$364))
A16: 10 | B16: =SUMPRODUCT(((INT((Schedule!$A$5:$A$364-1)/12)+1=10))*(Schedule!$AB$5:$AB$364)) | C16: =IFERROR(INDEX(Schedule!$L$5:$L$364,MATCH(1,((INT((Schedule!$A$5:$A$364-1)/12)+1=10))*(Schedule!$AB$5:$AB$364),0)),"") | D16: =IFERROR(INDEX(Schedule!$AA$5:$AA$364,MATCH(SUMPRODUCT(MAX(((INT((Schedule!$A$5:$A$364-1)/12)+1=10))*(Schedule!$AB$5:$AB$364)*(Schedule!$A$5:$A$364))),Schedule!$A$5:$A$364,0)),"") | E16: =SUMPRODUCT(((INT((Schedule!$A$5:$A$364-1)/12)+1=10))*(Schedule!$AB$5:$AB$364)*(Schedule!$T$5:$T$364)) | F16: =SUMPRODUCT(((INT((Schedule!$A$5:$A$364-1)/12)+1=10))*(Schedule!$AB$5:$AB$364)*(Schedule!$Y$5:$Y$364))
A17: 11 | B17: =SUMPRODUCT(((INT((Schedule!$A$5:$A$364-1)/12)+1=11))*(Schedule!$AB$5:$AB$364)) | C17: =IFERROR(INDEX(Schedule!$L$5:$L$364,MATCH(1,((INT((Schedule!$A$5:$A$364-1)/12)+1=11))*(Schedule!$AB$5:$AB$364),0)),"") | D17: =IFERROR(INDEX(Schedule!$AA$5:$AA$364,MATCH(SUMPRODUCT(MAX(((INT((Schedule!$A$5:$A$364-1)/12)+1=11))*(Schedule!$AB$5:$AB$364)*(Schedule!$A$5:$A$364))),Schedule!$A$5:$A$364,0)),"") | E17: =SUMPRODUCT(((INT((Schedule!$A$5:$A$364-1)/12)+1=11))*(Schedule!$AB$5:$AB$364)*(Schedule!$T$5:$T$364)) | F17: =SUMPRODUCT(((INT((Schedule!$A$5:$A$364-1)/12)+1=11))*(Schedule!$AB$5:$AB$364)*(Schedule!$Y$5:$Y$364))
A18: 12 | B18: =SUMPRODUCT(((INT((Schedule!$A$5:$A$364-1)/12)+1=12))*(Schedule!$AB$5:$AB$364)) | C18: =IFERROR(INDEX(Schedule!$L$5:$L$364,MATCH(1,((INT((Schedule!$A$5:$A$364-1)/12)+1=12))*(Schedule!$AB$5:$AB$364),0)),"") | D18: =IFERROR(INDEX(Schedule!$AA$5:$AA$364,MATCH(SUMPRODUCT(MAX(((INT((Schedule!$A$5:$A$364-1)/12)+1=12))*(Schedule!$AB$5:$AB$364)*(Schedule!$A$5:$A$364))),Schedule!$A$5:$A$364,0)),"") | E18: =SUMPRODUCT(((INT((Schedule!$A$5:$A$364-1)/12)+1=12))*(Schedule!$AB$5:$AB$364)*(Schedule!$T$5:$T$364)) | F18: =SUMPRODUCT(((INT((Schedule!$A$5:$A$364-1)/12)+1=12))*(Schedule!$AB$5:$AB$364)*(Schedule!$Y$5:$Y$364))
A19: 13 | B19: =SUMPRODUCT(((INT((Schedule!$A$5:$A$364-1)/12)+1=13))*(Schedule!$AB$5:$AB$364)) | C19: =IFERROR(INDEX(Schedule!$L$5:$L$364,MATCH(1,((INT((Schedule!$A$5:$A$364-1)/12)+1=13))*(Schedule!$AB$5:$AB$364),0)),"") | D19: =IFERROR(INDEX(Schedule!$AA$5:$AA$364,MATCH(SUMPRODUCT(MAX(((INT((Schedule!$A$5:$A$364-1)/12)+1=13))*(Schedule!$AB$5:$AB$364)*(Schedule!$A$5:$A$364))),Schedule!$A$5:$A$364,0)),"") | E19: =SUMPRODUCT(((INT((Schedule!$A$5:$A$364-1)/12)+1=13))*(Schedule!$AB$5:$AB$364)*(Schedule!$T$5:$T$364)) | F19: =SUMPRODUCT(((INT((Schedule!$A$5:$A$364-1)/12)+1=13))*(Schedule!$AB$5:$AB$364)*(Schedule!$Y$5:$Y$364))
A20: 14 | B20: =SUMPRODUCT(((INT((Schedule!$A$5:$A$364-1)/12)+1=14))*(Schedule!$AB$5:$AB$364)) | C20: =IFERROR(INDEX(Schedule!$L$5:$L$364,MATCH(1,((INT((Schedule!$A$5:$A$364-1)/12)+1=14))*(Schedule!$AB$5:$AB$364),0)),"") | D20: =IFERROR(INDEX(Schedule!$AA$5:$AA$364,MATCH(SUMPRODUCT(MAX(((INT((Schedule!$A$5:$A$364-1)/12)+1=14))*(Schedule!$AB$5:$AB$364)*(Schedule!$A$5:$A$364))),Schedule!$A$5:$A$364,0)),"") | E20: =SUMPRODUCT(((INT((Schedule!$A$5:$A$364-1)/12)+1=14))*(Schedule!$AB$5:$AB$364)*(Schedule!$T$5:$T$364)) | F20: =SUMPRODUCT(((INT((Schedule!$A$5:$A$364-1)/12)+1=14))*(Schedule!$AB$5:$AB$364)*(Schedule!$Y$5:$Y$364))
A21: 15 | B21: =SUMPRODUCT(((INT((Schedule!$A$5:$A$364-1)/12)+1=15))*(Schedule!$AB$5:$AB$364)) | C21: =IFERROR(INDEX(Schedule!$L$5:$L$364,MATCH(1,((INT((Schedule!$A$5:$A$364-1)/12)+1=15))*(Schedule!$AB$5:$AB$364),0)),"") | D21: =IFERROR(INDEX(Schedule!$AA$5:$AA$364,MATCH(SUMPRODUCT(MAX(((INT((Schedule!$A$5:$A$364-1)/12)+1=15))*(Schedule!$AB$5:$AB$364)*(Schedule!$A$5:$A$364))),Schedule!$A$5:$A$364,0)),"") | E21: =SUMPRODUCT(((INT((Schedule!$A$5:$A$364-1)/12)+1=15))*(Schedule!$AB$5:$AB$364)*(Schedule!$T$5:$T$364)) | F21: =SUMPRODUCT(((INT((Schedule!$A$5:$A$364-1)/12)+1=15))*(Schedule!$AB$5:$AB$364)*(Schedule!$Y$5:$Y$364))
A22: 16 | B22: =SUMPRODUCT(((INT((Schedule!$A$5:$A$364-1)/12)+1=16))*(Schedule!$AB$5:$AB$364)) | C22: =IFERROR(INDEX(Schedule!$L$5:$L$364,MATCH(1,((INT((Schedule!$A$5:$A$364-1)/12)+1=16))*(Schedule!$AB$5:$AB$364),0)),"") | D22: =IFERROR(INDEX(Schedule!$AA$5:$AA$364,MATCH(SUMPRODUCT(MAX(((INT((Schedule!$A$5:$A$364-1)/12)+1=16))*(Schedule!$AB$5:$AB$364)*(Schedule!$A$5:$A$364))),Schedule!$A$5:$A$364,0)),"") | E22: =SUMPRODUCT(((INT((Schedule!$A$5:$A$364-1)/12)+1=16))*(Schedule!$AB$5:$AB$364)*(Schedule!$T$5:$T$364)) | F22: =SUMPRODUCT(((INT((Schedule!$A$5:$A$364-1)/12)+1=16))*(Schedule!$AB$5:$AB$364)*(Schedule!$Y$5:$Y$364))
A23: 17 | B23: =SUMPRODUCT(((INT((Schedule!$A$5:$A$364-1)/12)+1=17))*(Schedule!$AB$5:$AB$364)) | C23: =IFERROR(INDEX(Schedule!$L$5:$L$364,MATCH(1,((INT((Schedule!$A$5:$A$364-1)/12)+1=17))*(Schedule!$AB$5:$AB$364),0)),"") | D23: =IFERROR(INDEX(Schedule!$AA$5:$AA$364,MATCH(SUMPRODUCT(MAX(((INT((Schedule!$A$5:$A$364-1)/12)+1=17))*(Schedule!$AB$5:$AB$364)*(Schedule!$A$5:$A$364))),Schedule!$A$5:$A$364,0)),"") | E23: =SUMPRODUCT(((INT((Schedule!$A$5:$A$364-1)/12)+1=17))*(Schedule!$AB$5:$AB$364)*(Schedule!$T$5:$T$364)) | F23: =SUMPRODUCT(((INT((Schedule!$A$5:$A$364-1)/12)+1=17))*(Schedule!$AB$5:$AB$364)*(Schedule!$Y$5:$Y$364))
A24: 18 | B24: =SUMPRODUCT(((INT((Schedule!$A$5:$A$364-1)/12)+1=18))*(Schedule!$AB$5:$AB$364)) | C24: =IFERROR(INDEX(Schedule!$L$5:$L$364,MATCH(1,((INT((Schedule!$A$5:$A$364-1)/12)+1=18))*(Schedule!$AB$5:$AB$364),0)),"") | D24: =IFERROR(INDEX(Schedule!$AA$5:$AA$364,MATCH(SUMPRODUCT(MAX(((INT((Schedule!$A$5:$A$364-1)/12)+1=18))*(Schedule!$AB$5:$AB$364)*(Schedule!$A$5:$A$364))),Schedule!$A$5:$A$364,0)),"") | E24: =SUMPRODUCT(((INT((Schedule!$A$5:$A$364-1)/12)+1=18))*(Schedule!$AB$5:$AB$364)*(Schedule!$T$5:$T$364)) | F24: =SUMPRODUCT(((INT((Schedule!$A$5:$A$364-1)/12)+1=18))*(Schedule!$AB$5:$AB$364)*(Schedule!$Y$5:$Y$364))
A25: 19 | B25: =SUMPRODUCT(((INT((Schedule!$A$5:$A$364-1)/12)+1=19))*(Schedule!$AB$5:$AB$364)) | C25: =IFERROR(INDEX(Schedule!$L$5:$L$364,MATCH(1,((INT((Schedule!$A$5:$A$364-1)/12)+1=19))*(Schedule!$AB$5:$AB$364),0)),"") | D25: =IFERROR(INDEX(Schedule!$AA$5:$AA$364,MATCH(SUMPRODUCT(MAX(((INT((Schedule!$A$5:$A$364-1)/12)+1=19))*(Schedule!$AB$5:$AB$364)*(Schedule!$A$5:$A$364))),Schedule!$A$5:$A$364,0)),"") | E25: =SUMPRODUCT(((INT((Schedule!$A$5:$A$364-1)/12)+1=19))*(Schedule!$AB$5:$AB$364)*(Schedule!$T$5:$T$364)) | F25: =SUMPRODUCT(((INT((Schedule!$A$5:$A$364-1)/12)+1=19))*(Schedule!$AB$5:$AB$364)*(Schedule!$Y$5:$Y$364))
A26: 20 | B26: =SUMPRODUCT(((INT((Schedule!$A$5:$A$364-1)/12)+1=20))*(Schedule!$AB$5:$AB$364)) | C26: =IFERROR(INDEX(Schedule!$L$5:$L$364,MATCH(1,((INT((Schedule!$A$5:$A$364-1)/12)+1=20))*(Schedule!$AB$5:$AB$364),0)),"") | D26: =IFERROR(INDEX(Schedule!$AA$5:$AA$364,MATCH(SUMPRODUCT(MAX(((INT((Schedule!$A$5:$A$364-1)/12)+1=20))*(Schedule!$AB$5:$AB$364)*(Schedule!$A$5:$A$364))),Schedule!$A$5:$A$364,0)),"") | E26: =SUMPRODUCT(((INT((Schedule!$A$5:$A$364-1)/12)+1=20))*(Schedule!$AB$5:$AB$364)*(Schedule!$T$5:$T$364)) | F26: =SUMPRODUCT(((INT((Schedule!$A$5:$A$364-1)/12)+1=20))*(Schedule!$AB$5:$AB$364)*(Schedule!$Y$5:$Y$364))
A27: 21 | B27: =SUMPRODUCT(((INT((Schedule!$A$5:$A$364-1)/12)+1=21))*(Schedule!$AB$5:$AB$364)) | C27: =IFERROR(INDEX(Schedule!$L$5:$L$364,MATCH(1,((INT((Schedule!$A$5:$A$364-1)/12)+1=21))*(Schedule!$AB$5:$AB$364),0)),"") | D27: =IFERROR(INDEX(Schedule!$AA$5:$AA$364,MATCH(SUMPRODUCT(MAX(((INT((Schedule!$A$5:$A$364-1)/12)+1=21))*(Schedule!$AB$5:$AB$364)*(Schedule!$A$5:$A$364))),Schedule!$A$5:$A$364,0)),"") | E27: =SUMPRODUCT(((INT((Schedule!$A$5:$A$364-1)/12)+1=21))*(Schedule!$AB$5:$AB$364)*(Schedule!$T$5:$T$364)) | F27: =SUMPRODUCT(((INT((Schedule!$A$5:$A$364-1)/12)+1=21))*(Schedule!$AB$5:$AB$364)*(Schedule!$Y$5:$Y$364))
A28: 22 | B28: =SUMPRODUCT(((INT((Schedule!$A$5:$A$364-1)/12)+1=22))*(Schedule!$AB$5:$AB$364)) | C28: =IFERROR(INDEX(Schedule!$L$5:$L$364,MATCH(1,((INT((Schedule!$A$5:$A$364-1)/12)+1=22))*(Schedule!$AB$5:$AB$364),0)),"") | D28: =IFERROR(INDEX(Schedule!$AA$5:$AA$364,MATCH(SUMPRODUCT(MAX(((INT((Schedule!$A$5:$A$364-1)/12)+1=22))*(Schedule!$AB$5:$AB$364)*(Schedule!$A$5:$A$364))),Schedule!$A$5:$A$364,0)),"") | E28: =SUMPRODUCT(((INT((Schedule!$A$5:$A$364-1)/12)+1=22))*(Schedule!$AB$5:$AB$364)*(Schedule!$T$5:$T$364)) | F28: =SUMPRODUCT(((INT((Schedule!$A$5:$A$364-1)/12)+1=22))*(Schedule!$AB$5:$AB$364)*(Schedule!$Y$5:$Y$364))
A29: 23 | B29: =SUMPRODUCT(((INT((Schedule!$A$5:$A$364-1)/12)+1=23))*(Schedule!$AB$5:$AB$364)) | C29: =IFERROR(INDEX(Schedule!$L$5:$L$364,MATCH(1,((INT((Schedule!$A$5:$A$364-1)/12)+1=23))*(Schedule!$AB$5:$AB$364),0)),"") | D29: =IFERROR(INDEX(Schedule!$AA$5:$AA$364,MATCH(SUMPRODUCT(MAX(((INT((Schedule!$A$5:$A$364-1)/12)+1=23))*(Schedule!$AB$5:$AB$364)*(Schedule!$A$5:$A$364))),Schedule!$A$5:$A$364,0)),"") | E29: =SUMPRODUCT(((INT((Schedule!$A$5:$A$364-1)/12)+1=23))*(Schedule!$AB$5:$AB$364)*(Schedule!$T$5:$T$364)) | F29: =SUMPRODUCT(((INT((Schedule!$A$5:$A$364-1)/12)+1=23))*(Schedule!$AB$5:$AB$364)*(Schedule!$Y$5:$Y$364))
A30: 24 | B30: =SUMPRODUCT(((INT((Schedule!$A$5:$A$364-1)/12)+1=24))*(Schedule!$AB$5:$AB$364)) | C30: =IFERROR(INDEX(Schedule!$L$5:$L$364,MATCH(1,((INT((Schedule!$A$5:$A$364-1)/12)+1=24))*(Schedule!$AB$5:$AB$364),0)),"") | D30: =IFERROR(INDEX(Schedule!$AA$5:$AA$364,MATCH(SUMPRODUCT(MAX(((INT((Schedule!$A$5:$A$364-1)/12)+1=24))*(Schedule!$AB$5:$AB$364)*(Schedule!$A$5:$A$364))),Schedule!$A$5:$A$364,0)),"") | E30: =SUMPRODUCT(((INT((Schedule!$A$5:$A$364-1)/12)+1=24))*(Schedule!$AB$5:$AB$364)*(Schedule!$T$5:$T$364)) | F30: =SUMPRODUCT(((INT((Schedule!$A$5:$A$364-1)/12)+1=24))*(Schedule!$AB$5:$AB$364)*(Schedule!$Y$5:$Y$364))
A31: 25 | B31: =SUMPRODUCT(((INT((Schedule!$A$5:$A$364-1)/12)+1=25))*(Schedule!$AB$5:$AB$364)) | C31: =IFERROR(INDEX(Schedule!$L$5:$L$364,MATCH(1,((INT((Schedule!$A$5:$A$364-1)/12)+1=25))*(Schedule!$AB$5:$AB$364),0)),"") | D31: =IFERROR(INDEX(Schedule!$AA$5:$AA$364,MATCH(SUMPRODUCT(MAX(((INT((Schedule!$A$5:$A$364-1)/12)+1=25))*(Schedule!$AB$5:$AB$364)*(Schedule!$A$5:$A$364))),Schedule!$A$5:$A$364,0)),"") | E31: =SUMPRODUCT(((INT((Schedule!$A$5:$A$364-1)/12)+1=25))*(Schedule!$AB$5:$AB$364)*(Schedule!$T$5:$T$364)) | F31: =SUMPRODUCT(((INT((Schedule!$A$5:$A$364-1)/12)+1=25))*(Schedule!$AB$5:$AB$364)*(Schedule!$Y$5:$Y$364))
A32: 26 | B32: =SUMPRODUCT(((INT((Schedule!$A$5:$A$364-1)/12)+1=26))*(Schedule!$AB$5:$AB$364)) | C32: =IFERROR(INDEX(Schedule!$L$5:$L$364,MATCH(1,((INT((Schedule!$A$5:$A$364-1)/12)+1=26))*(Schedule!$AB$5:$AB$364),0)),"") | D32: =IFERROR(INDEX(Schedule!$AA$5:$AA$364,MATCH(SUMPRODUCT(MAX(((INT((Schedule!$A$5:$A$364-1)/12)+1=26))*(Schedule!$AB$5:$AB$364)*(Schedule!$A$5:$A$364))),Schedule!$A$5:$A$364,0)),"") | E32: =SUMPRODUCT(((INT((Schedule!$A$5:$A$364-1)/12)+1=26))*(Schedule!$AB$5:$AB$364)*(Schedule!$T$5:$T$364)) | F32: =SUMPRODUCT(((INT((Schedule!$A$5:$A$364-1)/12)+1=26))*(Schedule!$AB$5:$AB$364)*(Schedule!$Y$5:$Y$364))
A33: 27 | B33: =SUMPRODUCT(((INT((Schedule!$A$5:$A$364-1)/12)+1=27))*(Schedule!$AB$5:$AB$364)) | C33: =IFERROR(INDEX(Schedule!$L$5:$L$364,MATCH(1,((INT((Schedule!$A$5:$A$364-1)/12)+1=27))*(Schedule!$AB$5:$AB$364),0)),"") | D33: =IFERROR(INDEX(Schedule!$AA$5:$AA$364,MATCH(SUMPRODUCT(MAX(((INT((Schedule!$A$5:$A$364-1)/12)+1=27))*(Schedule!$AB$5:$AB$364)*(Schedule!$A$5:$A$364))),Schedule!$A$5:$A$364,0)),"") | E33: =SUMPRODUCT(((INT((Schedule!$A$5:$A$364-1)/12)+1=27))*(Schedule!$AB$5:$AB$364)*(Schedule!$T$5:$T$364)) | F33: =SUMPRODUCT(((INT((Schedule!$A$5:$A$364-1)/12)+1=27))*(Schedule!$AB$5:$AB$364)*(Schedule!$Y$5:$Y$364))
A34: 28 | B34: =SUMPRODUCT(((INT((Schedule!$A$5:$A$364-1)/12)+1=28))*(Schedule!$AB$5:$AB$364)) | C34: =IFERROR(INDEX(Schedule!$L$5:$L$364,MATCH(1,((INT((Schedule!$A$5:$A$364-1)/12)+1=28))*(Schedule!$AB$5:$AB$364),0)),"") | D34: =IFERROR(INDEX(Schedule!$AA$5:$AA$364,MATCH(SUMPRODUCT(MAX(((INT((Schedule!$A$5:$A$364-1)/12)+1=28))*(Schedule!$AB$5:$AB$364)*(Schedule!$A$5:$A$364))),Schedule!$A$5:$A$364,0)),"") | E34: =SUMPRODUCT(((INT((Schedule!$A$5:$A$364-1)/12)+1=28))*(Schedule!$AB$5:$AB$364)*(Schedule!$T$5:$T$364)) | F34: =SUMPRODUCT(((INT((Schedule!$A$5:$A$364-1)/12)+1=28))*(Schedule!$AB$5:$AB$364)*(Schedule!$Y$5:$Y$364))
A35: 29 | B35: =SUMPRODUCT(((INT((Schedule!$A$5:$A$364-1)/12)+1=29))*(Schedule!$AB$5:$AB$364)) | C35: =IFERROR(INDEX(Schedule!$L$5:$L$364,MATCH(1,((INT((Schedule!$A$5:$A$364-1)/12)+1=29))*(Schedule!$AB$5:$AB$364),0)),"") | D35: =IFERROR(INDEX(Schedule!$AA$5:$AA$364,MATCH(SUMPRODUCT(MAX(((INT((Schedule!$A$5:$A$364-1)/12)+1=29))*(Schedule!$AB$5:$AB$364)*(Schedule!$A$5:$A$364))),Schedule!$A$5:$A$364,0)),"") | E35: =SUMPRODUCT(((INT((Schedule!$A$5:$A$364-1)/12)+1=29))*(Schedule!$AB$5:$AB$364)*(Schedule!$T$5:$T$364)) | F35: =SUMPRODUCT(((INT((Schedule!$A$5:$A$364-1)/12)+1=29))*(Schedule!$AB$5:$AB$364)*(Schedule!$Y$5:$Y$364))
A36: 30 | B36: =SUMPRODUCT(((INT((Schedule!$A$5:$A$364-1)/12)+1=30))*(Schedule!$AB$5:$AB$364)) | C36: =IFERROR(INDEX(Schedule!$L$5:$L$364,MATCH(1,((INT((Schedule!$A$5:$A$364-1)/12)+1=30))*(Schedule!$AB$5:$AB$364),0)),"") | D36: =IFERROR(INDEX(Schedule!$AA$5:$AA$364,MATCH(SUMPRODUCT(MAX(((INT((Schedule!$A$5:$A$364-1)/12)+1=30))*(Schedule!$AB$5:$AB$364)*(Schedule!$A$5:$A$364))),Schedule!$A$5:$A$364,0)),"") | E36: =SUMPRODUCT(((INT((Schedule!$A$5:$A$364-1)/12)+1=30))*(Schedule!$AB$5:$AB$364)*(Schedule!$T$5:$T$364)) | F36: =SUMPRODUCT(((INT((Schedule!$A$5:$A$364-1)/12)+1=30))*(Schedule!$AB$5:$AB$364)*(Schedule!$Y$5:$Y$364))
A38: Totals through year (see B4) | B38: =SUMIFS($E$7:$E$36,$A$7:$A$36,"<="&B4) | C38: =SUMIFS($F$7:$F$36,$A$7:$A$36,"<="&B4) | D38: =INDEX($D$7:$D$36,MATCH(MIN(B4,COUNT($A$7:$A$36)),$A$7:$A$36,0))
A39: (Interest / Principal / Ending balance)

Sheet PaymentFrequency
A1: Payment Frequency (monthly / semi-monthly / biweekly / weekly)
A2: Standalone single-loan calculator (not part of the segmented engine). Genuine per-period amortization at the chosen cadence. Bounded to 1560 periods (30 years at weekly, the densest cadence).
A4: Loan amount ($) | B4: 300000 | D4: Frequency | E4: Payments/Yr | F4: Payment Fraction
A5: Annual interest rate (%) | B5: 6.5 | D5: monthly | E5: 12 | F5: 1
A6: Term (months) | B6: 360 | D6: semiMonthly | E6: 24 | F6: 0.5
A7: Start date | B7: 2024-01-01 | D7: biweekly | E7: 26 | F7: 0.5
A8: Frequency (monthly/semiMonthly/biweekly/weekly) | B8: biweekly | D8: weekly | E8: 52 | F8: 0.25
A10: Payments per year (looked up) | B10: =INDEX($E$5:$E$8,MATCH(B8,$D$5:$D$8,0))
A11: Payment fraction (looked up) | B11: =INDEX($F$5:$F$8,MATCH(B8,$D$5:$D$8,0))
A12: Monthly-equivalent payment | B12: =ROUND(-PMT(B5/100/12,B6,B4),2)
A13: Period payment amount | B13: =ROUND(B12*B11,2)
A14: Number of periods to payoff | B14: =IFERROR(MATCH(0,$F$17:$F$1576,0),"loan does not pay off within 1560 periods -- extend the table")
A15: Total interest (this frequency) | B15: =SUM($D$17:$D$1576)
A16: Period # | B16: Period Date | C16: Payment | D16: Interest | E16: Principal | F16: Remaining Balance
